Workbook
Name Human_capital: Levers!$B$9:$D$9
Name Marketing: Levers!$B$7:$E$7
Name Pricing_Strategy: Levers!$B$6:$E$6
Name R_D_Strategy: Levers!$B$3:$F$3
Name Spiral: Levers!$B$5:$D$5
Name Supply_Chain: Levers!$B$8:$E$8
Name symmetrical: Levers!$B$4:$D$4

Sheet Instructions
B1: Johnson & Johnson University Case Competition
B2: Instructions
B4: Introduction:
B5: Thank you for participating in the Johnson & Johnson University Case Competition. This model should be very intuitive to use. We want you to concentrate on the STRATEGY and explaining the WHY behind the numbers and decisions. Once you select your decisions, the numbers will fall into place. Make sure each decision you make is justified and you can defend the reasoning behind your choice. Also, it is important that your decisions are consistent with the overall strategy your team chooses.
B7: Instructions:
B8: In the following "Decision Points" tab, you will see the decisions points listed out. All decisions points should be set to "base" when you open the excel. Please note that you must make a choice for each decision point and you cannot leave any options as "base" unless you choose Outsource for Supply Chain. If Outsource is chosen for Supply Chain, then base chould be selected for Human Capital as these two choices are inclusive. You can use the "Sandbox" tab to pull in data from other tabs for further Analysis Once you have finished your selectinos and the model has computed your Financials, ensure you can defend and state a reason behind why you have made each decision. They should all work together cohesively!
B10: Good Luck & Have Fun!

Sheet Decision Points
B1: Johnson & Johnson University Case Competition
B2: Decision Points
B4: Decision Point | C4: Decision
B5: R&D Strategy: | C5: ="Symmetrical: "&C6&", "&"Spiral: "&C7 -> Symmetrical: Base, Spiral: Base
B6: Symmetrical | C6: Base
B7: Spiral | C7: Base
B8: Pricing Strategy | C8: Base
B9: Marketing | C9: Silver | D9: Low
B10: Supply Chain | C10: Base | D10: Medium | E10: *If Outsource is chosen…
B11: Human Capital | C11: Base | D11: High | E11: … then base should be selected

Sheet Income Statement
B1: Johnson & Johnson University Case Competition
B2: Income Statement
C4: 5800000 | D4: 5961166 | E4: 6550428.5 | F4: 6952100.7 | G4: 7398217 | H4: 7846549 | I4: 8351631.4 | J4: 8893902.8 | K4: 9502334.7 | L4: 10079126 | M4: 10646884 | N4: 88182340
B5: *Financial statements are ficticious and not based on actual results
B6: $ in 000's | C6: Year 0 | D6: Year 1 | E6: Year 2 | F6: Year 3 | G6: Year 4 | H6: Year 5 | I6: Year 6 | J6: Year 7 | K6: Year 8 | L6: Year 9 | M6: Year 10 | N6: Cumu
B7: Net Sales | C7: =5600*1000 -> 5600000 | D7: =+(C7*(1+D8)) -> 5985112 | E7: =+(D7*(1+E8)) -> 6402154.6 | F7: =+(E7*(1+F8)) -> 6836348.7 | G7: =+(F7*(1+G8)) -> 7319473.5 | H7: =+(G7*(1+H8)) -> 7810610.2 | I7: =+(H7*(1+I8)) -> 8364148.1 | J7: =+(I7*(1+J8)) -> 8961599.2 | K7: =+(J7*(1+K8)) -> 9632912.6 | ... M7: =+(L7*(1+M8)) -> 10926152 | N7: =SUM(C7:M7) -> 88118755
B8: Net Sales Sales Growth Rate | C8: 0 | D8: {=0.06227*(1+_xlfn.SWITCH('Decision Points'!$C$10,"Base",0,"Outsource",'Supply Chain & Human Capital'!U6,"Plant Expansion",'Supply Chain & Human Capital'!U7,"New Plant Construction",'Supply Chain & Human Capital'!U8))+IF('Decision Points'!$C$8="Base",0,0)+IF('Decision Points'!$C$8="Low ",Levers!$B$13,0)+IF('Decision Points'!$C$8="Med",Levers!$B$14,0)+IF('Decision Points'!$C$8="High",Levers!$B$15,0)+IF('Decision Points'!$C$9="Base",0,0)+IF('Decision Points'!$C$9="Bronze",Levers!$B$18,0)+IF('Decision Points'!$C$9="Silver",Levers!$B$19,0)+IF('Decision Points'!$C$9="Gold",Levers!$B$20,0)+IF('Decision Points'!$C$6="Base",0,0)+IF('Decision Points'!$C$6=Levers!A29,Levers!$C$29,0)*0.75+IF('Decision Points'!$C$6=Levers!$A$30,Levers!$C$30,0)*0+IF('Decision Points'!$C$7="Base",0,0)+IF('Decision Points'!$C$7=Levers!$A$35,Levers!$C$35,0)*0+IF('Decision Points'!$C$7=Levers!$A$36,Levers!$C$36,0)*0.6} -> 0.06877 | E8: {=0.06318*(1+_xlfn.SWITCH('Decision Points'!$C$10,"Base",0,"Outsource",'Supply Chain & Human Capital'!V6,"Plant Expansion",'Supply Chain & Human Capital'!V7,"New Plant Construction",'Supply Chain & Human Capital'!V8))+IF('Decision Points'!$C$8="Base",0,0)+IF('Decision Points'!$C$8="Low ",Levers!$B$13,0)+IF('Decision Points'!$C$8="Med",Levers!$B$14,0)+IF('Decision Points'!$C$8="High",Levers!$B$15,0)+IF('Decision Points'!$C$9="Base",0,0)+IF('Decision Points'!$C$9="Bronze",Levers!$B$18,0)+IF('Decision Points'!$C$9="Silver",Levers!$B$19,0)+IF('Decision Points'!$C$9="Gold",Levers!$B$20,0)+IF('Decision Points'!$C$6="Base",0,0)+IF('Decision Points'!$C$6=Levers!A29,Levers!$C$29,0)*0.8+IF('Decision Points'!$C$6=Levers!$A$30,Levers!$C$30,0)*0.3+IF('Decision Points'!$C$7="Base",0,0)+IF('Decision Points'!$C$7=Levers!$A$35,Levers!$C$35,0)*0.4+IF('Decision Points'!$C$7=Levers!$A$36,Levers!$C$36,0)} -> 0.06968 | F8: {=0.06132*(1+_xlfn.SWITCH('Decision Points'!$C$10,"Base",0,"Outsource",'Supply Chain & Human Capital'!W6,"Plant Expansion",'Supply Chain & Human Capital'!W7,"New Plant Construction",'Supply Chain & Human Capital'!W8))+IF('Decision Points'!$C$8="Base",0,0)+IF('Decision Points'!$C$8="Low ",Levers!$B$13,0)+IF('Decision Points'!$C$8="Med",Levers!$B$14,0)+IF('Decision Points'!$C$8="High",Levers!$B$15,0)+IF('Decision Points'!$C$9="Base",0,0)+IF('Decision Points'!$C$9="Bronze",Levers!$B$18,0)+IF('Decision Points'!$C$9="Silver",Levers!$B$19,0)+IF('Decision Points'!$C$9="Gold",Levers!$B$20,0)+IF('Decision Points'!$C$6="Base",0,0)+IF('Decision Points'!$C$6=Levers!A29,Levers!$C$29,0)+IF('Decision Points'!$C$6=Levers!$A$30,Levers!$C$30,0)*0.5+IF('Decision Points'!$C$7="Base",0,0)+IF('Decision Points'!$C$7=Levers!$A$35,Levers!$C$35,0)*0.6+IF('Decision Points'!$C$7=Levers!$A$36,Levers!$C$36,0)} -> 0.06782 | G8: {=0.06417*(1+_xlfn.SWITCH('Decision Points'!$C$10,"Base",0,"Outsource",'Supply Chain & Human Capital'!X6,"Plant Expansion",'Supply Chain & Human Capital'!X7,"New Plant Construction",'Supply Chain & Human Capital'!X8))+IF('Decision Points'!$C$8="Base",0,0)+IF('Decision Points'!$C$8="Low ",Levers!$B$13,0)+IF('Decision Points'!$C$8="Med",Levers!$B$14,0)+IF('Decision Points'!$C$8="High",Levers!$B$15,0)+IF('Decision Points'!$C$9="Base",0,0)+IF('Decision Points'!$C$9="Bronze",Levers!$B$18,0)+IF('Decision Points'!$C$9="Silver",Levers!$B$19,0)+IF('Decision Points'!$C$9="Gold",Levers!$B$20,0)++IF('Decision Points'!$C$6="Base",0,0)+IF('Decision Points'!$C$6=Levers!A29,Levers!$C$29,0)+IF('Decision Points'!$C$6=Levers!$A$30,Levers!$C$30,0)*0.75+IF('Decision Points'!$C$7="Base",0,0)+IF('Decision Points'!$C$7=Levers!$A$35,Levers!$C$35,0)+IF('Decision Points'!$C$7=Levers!$A$36,Levers!$C$36,0)} -> 0.07067 | H8: {=0.0606*(1+_xlfn.SWITCH('Decision Points'!$C$10,"Base",0,"Outsource",'Supply Chain & Human Capital'!X6,"Plant Expansion",'Supply Chain & Human Capital'!X7,"New Plant Construction",'Supply Chain & Human Capital'!X8))+IF('Decision Points'!$C$8="Base",0,0)+IF('Decision Points'!$C$8="Low ",Levers!$B$13,0)+IF('Decision Points'!$C$8="Med",Levers!$B$14,0)+IF('Decision Points'!$C$8="High",Levers!$B$15,0)+IF('Decision Points'!$C$9="Base",0,0)+IF('Decision Points'!$C$9="Bronze",Levers!$B$18,0)+IF('Decision Points'!$C$9="Silver",Levers!$B$19,0)+IF('Decision Points'!$C$9="Gold",Levers!$B$20,0)++IF('Decision Points'!$C$6="Base",0,0)+IF('Decision Points'!$C$6=Levers!A29,Levers!$C$29,0)+IF('Decision Points'!$C$6=Levers!$A$30,Levers!$C$30,0)+IF('Decision Points'!$C$7="Base",0,0)+IF('Decision Points'!$C$7=Levers!$A$35,Levers!$C$35,0)+IF('Decision Points'!$C$7=Levers!$A$36,Levers!$C$36,0)} -> 0.0671 | I8: {=0.06437*(1+_xlfn.SWITCH('Decision Points'!$C$10,"Base",0,"Outsource",'Supply Chain & Human Capital'!X6,"Plant Expansion",'Supply Chain & Human Capital'!X7,"New Plant Construction",'Supply Chain & Human Capital'!X8))+IF('Decision Points'!$C$8="Base",0,0)+IF('Decision Points'!$C$8="Low ",Levers!$B$13,0)+IF('Decision Points'!$C$8="Med",Levers!$B$14,0)+IF('Decision Points'!$C$8="High",Levers!$B$15,0)+IF('Decision Points'!$C$9="Base",0,0)+IF('Decision Points'!$C$9="Bronze",Levers!$B$18,0)+IF('Decision Points'!$C$9="Silver",Levers!$B$19,0)+IF('Decision Points'!$C$9="Gold",Levers!$B$20,0)++IF('Decision Points'!$C$6="Base",0,0)+IF('Decision Points'!$C$6=Levers!A29,Levers!$C$29,0)+IF('Decision Points'!$C$6=Levers!$A$30,Levers!$C$30,0)+IF('Decision Points'!$C$7="Base",0,0)+IF('Decision Points'!$C$7=Levers!$A$35,Levers!$C$35,0)+IF('Decision Points'!$C$7=Levers!$A$36,Levers!$C$36,0)} -> 0.07087 | J8: {=0.06493*(1+_xlfn.SWITCH('Decision Points'!$C$10,"Base",0,"Outsource",'Supply Chain & Human Capital'!X6,"Plant Expansion",'Supply Chain & Human Capital'!X7,"New Plant Construction",'Supply Chain & Human Capital'!X8))+IF('Decision Points'!$C$8="Base",0,0)+IF('Decision Points'!$C$8="Low ",Levers!$B$13,0)+IF('Decision Points'!$C$8="Med",Levers!$B$14,0)+IF('Decision Points'!$C$8="High",Levers!$B$15,0)+IF('Decision Points'!$C$9="Base",0,0)+IF('Decision Points'!$C$9="Bronze",Levers!$B$18,0)+IF('Decision Points'!$C$9="Silver",Levers!$B$19,0)+IF('Decision Points'!$C$9="Gold",Levers!$B$20,0)++IF('Decision Points'!$C$6="Base",0,0)+IF('Decision Points'!$C$6=Levers!A29,Levers!$C$29,0)+IF('Decision Points'!$C$6=Levers!$A$30,Levers!$C$30,0)+IF('Decision Points'!$C$7="Base",0,0)+IF('Decision Points'!$C$7=Levers!$A$35,Levers!$C$35,0)+IF('Decision Points'!$C$7=Levers!$A$36,Levers!$C$36,0)} -> 0.07143 | K8: {=0.06841*(1+_xlfn.SWITCH('Decision Points'!$C$10,"Base",0,"Outsource",'Supply Chain & Human Capital'!X6,"Plant Expansion",'Supply Chain & Human Capital'!X7,"New Plant Construction",'Supply Chain & Human Capital'!X8))+IF('Decision Points'!$C$8="Base",0,0)+IF('Decision Points'!$C$8="Low ",Levers!$B$13,0)+IF('Decision Points'!$C$8="Med",Levers!$B$14,0)+IF('Decision Points'!$C$8="High",Levers!$B$15,0)+IF('Decision Points'!$C$9="Base",0,0)+IF('Decision Points'!$C$9="Bronze",Levers!$B$18,0)+IF('Decision Points'!$C$9="Silver",Levers!$B$19,0)+IF('Decision Points'!$C$9="Gold",Levers!$B$20,0)++IF('Decision Points'!$C$6="Base",0,0)+IF('Decision Points'!$C$6=Levers!A29,Levers!$C$29,0)+IF('Decision Points'!$C$6=Levers!$A$30,Levers!$C$30,0)+IF('Decision Points'!$C$7="Base",0,0)+IF('Decision Points'!$C$7=Levers!$A$35,Levers!$C$35,0)+IF('Decision Points'!$C$7=Levers!$A$36,Levers!$C$36,0)} -> 0.07491 | L8: {=0.0607*(1+_xlfn.SWITCH('Decision Points'!$C$10,"Base",0,"Outsource",'Supply Chain & Human Capital'!X6,"Plant Expansion",'Supply Chain & Human Capital'!X7,"New Plant Construction",'Supply Chain & Human Capital'!X8))+IF('Decision Points'!$C$8="Base",0,0)+IF('Decision Points'!$C$8="Low ",Levers!$B$13,0)+IF('Decision Points'!$C$8="Med",Levers!$B$14,0)+IF('Decision Points'!$C$8="High",Levers!$B$15,0)+IF('Decision Points'!$C$9="Base",0,0)+IF('Decision Points'!$C$9="Bronze",Levers!$B$18,0)+IF('Decision Points'!$C$9="Silver",Levers!$B$19,0)+IF('Decision Points'!$C$9="Gold",Levers!$B$20,0)++IF('Decision Points'!$C$6="Base",0,0)+IF('Decision Points'!$C$6=Levers!A29,Levers!$C$29,0)+IF('Decision Points'!$C$6=Levers!$A$30,Levers!$C$30,0)+IF('Decision Points'!$C$7="Base",0,0)+IF('Decision Points'!$C$7=Levers!$A$35,Levers!$C$35,0)+IF('Decision Points'!$C$7=Levers!$A$36,Levers!$C$36,0)} -> 0.0672 | M8: {=0.05633*(1+_xlfn.SWITCH('Decision Points'!$C$10,"Base",0,"Outsource",'Supply Chain & Human Capital'!X6,"Plant Expansion",'Supply Chain & Human Capital'!X7,"New Plant Construction",'Supply Chain & Human Capital'!X8))+IF('Decision Points'!$C$8="Base",0,0)+IF('Decision Points'!$C$8="Low ",Levers!$B$13,0)+IF('Decision Points'!$C$8="Med",Levers!$B$14,0)+IF('Decision Points'!$C$8="High",Levers!$B$15,0)+IF('Decision Points'!$C$9="Base",0,0)+IF('Decision Points'!$C$9="Bronze",Levers!$B$18,0)+IF('Decision Points'!$C$9="Silver",Levers!$B$19,0)+IF('Decision Points'!$C$9="Gold",Levers!$B$20,0)++IF('Decision Points'!$C$6="Base",0,0)+IF('Decision Points'!$C$6=Levers!A29,Levers!$C$29,0)+IF('Decision Points'!$C$6=Levers!$A$30,Levers!$C$30,0)+IF('Decision Points'!$C$7="Base",0,0)+IF('Decision Points'!$C$7=Levers!$A$35,Levers!$C$35,0)+IF('Decision Points'!$C$7=Levers!$A$36,Levers!$C$36,0)} -> 0.06283 | N8: 0
B10: Cost of Goods Sold | C10: =+C7*C12 -> 1730400 | D10: =+D4*D12 -> 1844980.9 | E10: =+E4*E12 -> 1999845.8 | F10: =+F4*F12 -> 2156541.7 | G10: =+G4*G12 -> 2259415.5 | H10: =+H4*H12 -> 2402613.3 | I10: =+I4*I12 -> 2585665.1 | J10: =+J4*J12 -> 2731317.5 | K10: =+K4*K12 -> 2937171.6 | ... M10: =+M4*M12 -> 3214294.2 | N10: =SUM(C10:M10) -> 26896063
B11: % of Sales | C11: =+C10/C7 -> 0.309 | D11: =+D10/D7 -> 0.30826171 | E11: =+E10/E7 -> 0.31237075 | F11: =+F10/F7 -> 0.31545226 | G11: =+G10/G7 -> 0.30868552 | H11: =+H10/H7 -> 0.30760891 | I11: =+I10/I7 -> 0.30913669 | J11: =+J10/J7 -> 0.30478015 | ... N11: =+N10/N7 -> 0.30522518
B12: COGS % of Baseline | C12: 0.309 | D12: {=0.3095*(1+_xlfn.SWITCH('Decision Points'!$C$10,"Base",0,"Outsource",'Supply Chain & Human Capital'!$C$6,"Plant Expansion",'Supply Chain & Human Capital'!H7,"New Plant Construction",'Supply Chain & Human Capital'!H8)+_xlfn.SWITCH('Decision Points'!$C$11,"Contractor ",'Supply Chain & Human Capital'!H11,"Full Time",'Supply Chain & Human Capital'!H12,"Base",0))} -> 0.3095 | E12: {=30.53%*(1+_xlfn.SWITCH('Decision Points'!$C$10,"Base",0,"Outsource",'Supply Chain & Human Capital'!$C$6,"Plant Expansion",'Supply Chain & Human Capital'!I7,"New Plant Construction",'Supply Chain & Human Capital'!I8)+_xlfn.SWITCH('Decision Points'!$C$11,"Contractor ",'Supply Chain & Human Capital'!I11,"Full Time",'Supply Chain & Human Capital'!I12,"Base",0))} -> 0.3053 | F12: {=31.02%*(1+_xlfn.SWITCH('Decision Points'!$C$10,"Base",0,"Outsource",'Supply Chain & Human Capital'!$C$6,"Plant Expansion",'Supply Chain & Human Capital'!J7,"New Plant Construction",'Supply Chain & Human Capital'!J8)+_xlfn.SWITCH('Decision Points'!$C$11,"Contractor ",'Supply Chain & Human Capital'!J11,"Full Time",'Supply Chain & Human Capital'!J12,"Base",0))} -> 0.3102 | G12: {=30.54%*(1+_xlfn.SWITCH('Decision Points'!$C$10,"Base",0,"Outsource",'Supply Chain & Human Capital'!$C$6,"Plant Expansion",'Supply Chain & Human Capital'!K7,"New Plant Construction",'Supply Chain & Human Capital'!K8)+_xlfn.SWITCH('Decision Points'!$C$11,"Contractor ",'Supply Chain & Human Capital'!K11,"Full Time",'Supply Chain & Human Capital'!K12,"Base",0))} -> 0.3054 | H12: {=30.62%*(1+_xlfn.SWITCH('Decision Points'!$C$10,"Base",0,"Outsource",'Supply Chain & Human Capital'!$C$6,"Plant Expansion",'Supply Chain & Human Capital'!K7,"New Plant Construction",'Supply Chain & Human Capital'!K8)+_xlfn.SWITCH('Decision Points'!$C$11,"Contractor ",'Supply Chain & Human Capital'!K11,"Full Time",'Supply Chain & Human Capital'!K12,"Base",0))} -> 0.3062 | I12: {=30.96%*(1+_xlfn.SWITCH('Decision Points'!$C$10,"Base",0,"Outsource",'Supply Chain & Human Capital'!$C$6,"Plant Expansion",'Supply Chain & Human Capital'!K7,"New Plant Construction",'Supply Chain & Human Capital'!K8)+_xlfn.SWITCH('Decision Points'!$C$11,"Contractor ",'Supply Chain & Human Capital'!K11,"Full Time",'Supply Chain & Human Capital'!K12,"Base",0))} -> 0.3096 | J12: {=30.71%*(1+_xlfn.SWITCH('Decision Points'!$C$10,"Base",0,"Outsource",'Supply Chain & Human Capital'!$C$6,"Plant Expansion",'Supply Chain & Human Capital'!K7,"New Plant Construction",'Supply Chain & Human Capital'!K8)+_xlfn.SWITCH('Decision Points'!$C$11,"Contractor ",'Supply Chain & Human Capital'!K11,"Full Time",'Supply Chain & Human Capital'!K12,"Base",0))} -> 0.3071 | K12: {=30.91%*(1+_xlfn.SWITCH('Decision Points'!$C$10,"Base",0,"Outsource",'Supply Chain & Human Capital'!$C$6,"Plant Expansion",'Supply Chain & Human Capital'!K7,"New Plant Construction",'Supply Chain & Human Capital'!K8)+_xlfn.SWITCH('Decision Points'!$C$11,"Contractor ",'Supply Chain & Human Capital'!K11,"Full Time",'Supply Chain & Human Capital'!O12,"Base",0))} -> 0.3091 | L12: {=30.1%*(1+_xlfn.SWITCH('Decision Points'!$C$10,"Base",0,"Outsource",'Supply Chain & Human Capital'!$C$6,"Plant Expansion",'Supply Chain & Human Capital'!K7,"New Plant Construction",'Supply Chain & Human Capital'!K8)+_xlfn.SWITCH('Decision Points'!$C$11,"Contractor ",'Supply Chain & Human Capital'!K11,"Full Time",'Supply Chain & Human Capital'!P12,"Base",0))} -> 0.301 | M12: {=30.19%*(1+_xlfn.SWITCH('Decision Points'!$C$10,"Base",0,"Outsource",'Supply Chain & Human Capital'!$C$6,"Plant Expansion",'Supply Chain & Human Capital'!K7,"New Plant Construction",'Supply Chain & Human Capital'!K8)+_xlfn.SWITCH('Decision Points'!$C$11,"Contractor ",'Supply Chain & Human Capital'!K11,"Full Time",'Supply Chain & Human Capital'!P12,"Base",0))} -> 0.3019
B14: Gross Profit | C14: =+C7-C10 -> 3869600 | D14: =+D7-D10 -> 4140131.1 | E14: =+E7-E10 -> 4402308.8 | F14: =+F7-F10 -> 4679807.1 | G14: =+G7-G10 -> 5060058 | H14: =+H7-H10 -> 5407996.9 | I14: =+I7-I10 -> 5778483 | J14: =+J7-J10 -> 6230281.7 | ... M14: =+M7-M10 -> 7711857.9 | N14: =SUM(C14:M14) -> 61222693
B15: % of Sales | C15: =+C14/C7 -> 0.691 | D15: =+D14/D7 -> 0.69173829 | E15: =+E14/E7 -> 0.68762925 | F15: =+F14/F7 -> 0.68454774 | G15: =+G14/G7 -> 0.69131448 | H15: =+H14/H7 -> 0.69239109 | I15: =+I14/I7 -> 0.69086331 | J15: =+J14/J7 -> 0.69521985 | ... M15: =+M14/M7 -> 0.70581646 | N15: =N14/$N$7 -> 0.69477482
B17: Selling, General & Administrative | C17: =+C4*C19 -> 1827000 | D17: =+D4*D19 -> 1926052.7 | E17: =+E4*E19 -> 2246141.9 | F17: =+F4*F19 -> 2337296.3 | G17: =+G4*G19 -> 2505036.3 | H17: =+H4*H19 -> 2691366.3 | I17: =+I4*I19 -> 2811159.1 | J17: =+J4*J19 -> 2979457.4 | ... M17: =+M4*M19 -> 3479401.6 | N17: =SUM(C17:M17) -> 29142493
B18: % of Sales | C18: =+C17/C7 -> 0.32625 | D18: =+D17/D7 -> 0.3218073 | E18: =+E17/E7 -> 0.35084156 | F18: =+F17/F7 -> 0.34189249 | G18: =+G17/G7 -> 0.34224269 | H18: =+H17/H7 -> 0.34457824 | I18: =+I17/I7 -> 0.33609629 | J18: =+J17/J7 -> 0.33246939 | ... N18: =+N17/N7 -> 0.33071839
B19: SG&A % of Baseline | C19: 0.315 | D19: =0.3031+IF('Decision Points'!$C$9="Base",0,0)+IF('Decision Points'!$C$9="Bronze",Levers!$B$23,0)+IF('Decision Points'!$C$9="Silver",Levers!$B$24,0)+IF('Decision Points'!$C$9="Gold",Levers!$B$25,0)+IF('Decision Points'!$C$10="Base",0,0)+IF('Decision Points'!$C$10="Outsource",0,0)+IF('Decision Points'!$C$10="Plant Expansion",'Supply Chain & Human Capital'!H22,0)+IF('Decision Points'!C10="New Plant Construction",'Supply Chain & Human Capital'!H23,0) -> 0.3231 | E19: =0.3229+IF('Decision Points'!$C$9="Base",0,0)+IF('Decision Points'!$C$9="Bronze",Levers!$B$23,0)+IF('Decision Points'!$C$9="Silver",Levers!$B$24,0)+IF('Decision Points'!$C$9="Gold",Levers!$B$25,0)+IF('Decision Points'!$C$10="Base",0,0)+IF('Decision Points'!$C$10="Outsource",0,0)+IF('Decision Points'!$C$10="Plant Expansion",'Supply Chain & Human Capital'!I22,0)+IF('Decision Points'!C10="New Plant Construction",'Supply Chain & Human Capital'!I23,0) -> 0.3429 | F19: =0.3162+IF('Decision Points'!$C$9="Base",0,0)+IF('Decision Points'!$C$9="Bronze",Levers!$B$23,0)+IF('Decision Points'!$C$9="Silver",Levers!$B$24,0)+IF('Decision Points'!$C$9="Gold",Levers!$B$25,0)+IF('Decision Points'!$C$10="Base",0,0)+IF('Decision Points'!$C$10="Outsource",0,0)+IF('Decision Points'!$C$10="Plant Expansion",'Supply Chain & Human Capital'!J22,0)+IF('Decision Points'!C10="New Plant Construction",'Supply Chain & Human Capital'!J23,0) -> 0.3362 | G19: =0.3186+IF('Decision Points'!$C$9="Base",0,0)+IF('Decision Points'!$C$9="Bronze",Levers!$B$23,0)+IF('Decision Points'!$C$9="Silver",Levers!$B$24,0)+IF('Decision Points'!$C$9="Gold",Levers!$B$25,0)+IF('Decision Points'!$C$10="Base",0,0)+IF('Decision Points'!$C$10="Outsource",0,0)+IF('Decision Points'!$C$10="Plant Expansion",'Supply Chain & Human Capital'!K22,0)+IF('Decision Points'!C10="New Plant Construction",'Supply Chain & Human Capital'!K23,0) -> 0.3386 | H19: =0.323+IF('Decision Points'!$C$9="Base",0,0)+IF('Decision Points'!$C$9="Bronze",Levers!$B$23,0)+IF('Decision Points'!$C$9="Silver",Levers!$B$24,0)+IF('Decision Points'!$C$9="Gold",Levers!$B$25,0)+IF('Decision Points'!$C$10="Base",0,0)+IF('Decision Points'!$C$10="Outsource",0,0)+IF('Decision Points'!$C$10="Plant Expansion",'Supply Chain & Human Capital'!L22,0)+IF('Decision Points'!C10="New Plant Construction",'Supply Chain & Human Capital'!L23,0) -> 0.343 | I19: =0.3166+IF('Decision Points'!$C$9="Base",0,0)+IF('Decision Points'!$C$9="Bronze",Levers!$B$23,0)+IF('Decision Points'!$C$9="Silver",Levers!$B$24,0)+IF('Decision Points'!$C$9="Gold",Levers!$B$25,0)+IF('Decision Points'!$C$10="Base",0,0)+IF('Decision Points'!$C$10="Outsource",0,0)+IF('Decision Points'!$C$10="Plant Expansion",'Supply Chain & Human Capital'!M22,0)+IF('Decision Points'!C10="New Plant Construction",'Supply Chain & Human Capital'!M23,0) -> 0.3366 | J19: =0.315+IF('Decision Points'!$C$9="Base",0,0)+IF('Decision Points'!$C$9="Bronze",Levers!$B$23,0)+IF('Decision Points'!$C$9="Silver",Levers!$B$24,0)+IF('Decision Points'!$C$9="Gold",Levers!$B$25,0)+IF('Decision Points'!$C$10="Base",0,0)+IF('Decision Points'!$C$10="Outsource",0,0)+IF('Decision Points'!$C$10="Plant Expansion",'Supply Chain & Human Capital'!M22,0)+IF('Decision Points'!C10="New Plant Construction",'Supply Chain & Human Capital'!M23,0) -> 0.335 | K19: =0.3071+IF('Decision Points'!$C$9="Base",0,0)+IF('Decision Points'!$C$9="Bronze",Levers!$B$23,0)+IF('Decision Points'!$C$9="Silver",Levers!$B$24,0)+IF('Decision Points'!$C$9="Gold",Levers!$B$25,0)+IF('Decision Points'!$C$10="Base",0,0)+IF('Decision Points'!$C$10="Outsource",0,0)+IF('Decision Points'!$C$10="Plant Expansion",'Supply Chain & Human Capital'!M22,0)+IF('Decision Points'!C10="New Plant Construction",'Supply Chain & Human Capital'!M23,0) -> 0.3271 | L19: =0.3006+IF('Decision Points'!$C$9="Base",0,0)+IF('Decision Points'!$C$9="Bronze",Levers!$B$23,0)+IF('Decision Points'!$C$9="Silver",Levers!$B$24,0)+IF('Decision Points'!$C$9="Gold",Levers!$B$25,0)+IF('Decision Points'!$C$10="Base",0,0)+IF('Decision Points'!$C$10="Outsource",0,0)+IF('Decision Points'!$C$10="Plant Expansion",'Supply Chain & Human Capital'!M22,0)+IF('Decision Points'!C10="New Plant Construction",'Supply Chain & Human Capital'!M23,0) -> 0.3206 | M19: =0.3068+IF('Decision Points'!$C$9="Base",0,0)+IF('Decision Points'!$C$9="Bronze",Levers!$B$23,0)+IF('Decision Points'!$C$9="Silver",Levers!$B$24,0)+IF('Decision Points'!$C$9="Gold",Levers!$B$25,0)+IF('Decision Points'!$C$10="Base",0,0)+IF('Decision Points'!$C$10="Outsource",0,0)+IF('Decision Points'!$C$10="Plant Expansion",'Supply Chain & Human Capital'!M22,0)+IF('Decision Points'!C10="New Plant Construction",'Supply Chain & Human Capital'!M23,0) -> 0.3268
B21: Research & Development | C21: =+C7*C23 -> 291200 | D21: =+D4*D23+IF('Decision Points'!$C$6=Levers!$A$30,50000,0)+IF('Decision Points'!$C$7=Levers!$A$36,75000,0) -> 327268.01 | E21: =+E4*E23+IF('Decision Points'!$C$6=Levers!$A$30,60000,0)+IF('Decision Points'!$C$7=Levers!$A$36,85000,0) -> 355688.27 | F21: =+F4*F23+IF('Decision Points'!$C$6=Levers!$A$30,25000,0)+IF('Decision Points'!$C$7=Levers!$A$36,35500,0) -> 346909.83 | G21: =+G4*G23 -> 383967.46 | H21: =+H4*H23 -> 386834.87 | I21: =+I4*I23 -> 449317.77 | J21: =+J4*J23 -> 483828.31 | K21: =+K4*K23 -> 493171.17 | L21: =+L4*L23 -> 553344.04 | M21: =+M4*M23 -> 521697.3 | N21: =SUM(C21:M21) -> 4593227
B22: % of Sales | C22: =+C21/C7 -> 0.052 | D22: =+D21/D7 -> 0.054680349 | E22: =+E21/E7 -> 0.055557588 | F22: =+F21/F7 -> 0.050744899 | G22: =+G21/G7 -> 0.052458345 | H22: =+H21/H7 -> 0.049526843 | I22: =+I21/I7 -> 0.05371949 | J22: =+J21/J7 -> 0.053989059 | ... N22: =+N21/N7 -> 0.052125419
B23: R&D % of Baseline | C23: 0.052 | D23: =0.0549+IF('Decision Points'!$C$6="Base",0,0)+IF('Decision Points'!$C$6=Levers!A29,Levers!$B$29,0)+IF('Decision Points'!$C$6=Levers!$A$30,Levers!$B$30,0)+IF('Decision Points'!$C$7="Base",0,0)+IF('Decision Points'!$C$7=Levers!$A$35,Levers!$B$35,0)+IF('Decision Points'!$C$7=Levers!$A$36,Levers!$B$36,0) -> 0.0549 | E23: =0.0543+IF('Decision Points'!$C$6="Base",0,0)+IF('Decision Points'!$C$6=Levers!A29,Levers!$B$29,0)+IF('Decision Points'!$C$6=Levers!$A$30,Levers!$B$30,0)+IF('Decision Points'!$C$7="Base",0,0)+IF('Decision Points'!$C$7=Levers!$A$35,Levers!$B$35,0)+IF('Decision Points'!$C$7=Levers!$A$36,Levers!$B$36,0) -> 0.0543 | F23: =0.0499+IF('Decision Points'!$C$6="Base",0,0)+IF('Decision Points'!$C$6=Levers!A29,Levers!$B$29,0)+IF('Decision Points'!$C$6=Levers!$A$30,Levers!$B$30,0)+IF('Decision Points'!$C$7="Base",0,0)+IF('Decision Points'!$C$7=Levers!$A$35,Levers!$B$35,0)+IF('Decision Points'!$C$7=Levers!$A$36,Levers!$B$36,0) -> 0.0499 | G23: =0.0519+IF('Decision Points'!$C$6="Base",0,0)+IF('Decision Points'!$C$6=Levers!A29,Levers!$B$29,0)+IF('Decision Points'!$C$6=Levers!$A$30,Levers!$B$30,0)+IF('Decision Points'!$C$7="Base",0,0)+IF('Decision Points'!$C$7=Levers!$A$35,Levers!$B$35,0)+IF('Decision Points'!$C$7=Levers!$A$36,Levers!$B$36,0) -> 0.0519 | H23: =0.0493+IF('Decision Points'!$C$6="Base",0,0)+IF('Decision Points'!$C$6=Levers!A29,Levers!$B$29,0)+IF('Decision Points'!$C$6=Levers!$A$30,Levers!$B$30,0)+IF('Decision Points'!$C$7="Base",0,0)+IF('Decision Points'!$C$7=Levers!$A$35,Levers!$B$35,0)+IF('Decision Points'!$C$7=Levers!$A$36,Levers!$B$36,0) -> 0.0493 | I23: =0.0538+IF('Decision Points'!$C$6="Base",0,0)+IF('Decision Points'!$C$6=Levers!A29,Levers!$B$29,0)+IF('Decision Points'!$C$6=Levers!$A$30,Levers!$B$30,0)+IF('Decision Points'!$C$7="Base",0,0)+IF('Decision Points'!$C$7=Levers!$A$35,Levers!$B$35,0)+IF('Decision Points'!$C$7=Levers!$A$36,Levers!$B$36,0) -> 0.0538 | J23: =0.0544+IF('Decision Points'!$C$6="Base",0,0)+IF('Decision Points'!$C$6=Levers!A29,Levers!$B$29,0)+IF('Decision Points'!$C$6=Levers!$A$30,Levers!$B$30,0)+IF('Decision Points'!$C$7="Base",0,0)+IF('Decision Points'!$C$7=Levers!$A$35,Levers!$B$35,0)+IF('Decision Points'!$C$7=Levers!$A$36,Levers!$B$36,0) -> 0.0544 | K23: =0.0519+IF('Decision Points'!$C$6="Base",0,0)+IF('Decision Points'!$C$6=Levers!A29,Levers!$B$29,0)+IF('Decision Points'!$C$6=Levers!$A$30,Levers!$B$30,0)+IF('Decision Points'!$C$7="Base",0,0)+IF('Decision Points'!$C$7=Levers!$A$35,Levers!$B$35,0)+IF('Decision Points'!$C$7=Levers!$A$36,Levers!$B$36,0) -> 0.0519 | L23: =0.0549+IF('Decision Points'!$C$6="Base",0,0)+IF('Decision Points'!$C$6=Levers!A29,Levers!$B$29,0)+IF('Decision Points'!$C$6=Levers!$A$30,Levers!$B$30,0)+IF('Decision Points'!$C$7="Base",0,0)+IF('Decision Points'!$C$7=Levers!$A$35,Levers!$B$35,0)+IF('Decision Points'!$C$7=Levers!$A$36,Levers!$B$36,0) -> 0.0549 | M23: =0.049+IF('Decision Points'!$C$6="Base",0,0)+IF('Decision Points'!$C$6=Levers!A29,Levers!$B$29,0)+IF('Decision Points'!$C$6=Levers!$A$30,Levers!$B$30,0)+IF('Decision Points'!$C$7="Base",0,0)+IF('Decision Points'!$C$7=Levers!$A$35,Levers!$B$35,0)+IF('Decision Points'!$C$7=Levers!$A$36,Levers!$B$36,0) -> 0.049
B25: Operational Expenditures | C25: =+C21+C17 -> 2118200 | D25: =+D21+D17 -> 2253320.7 | E25: =+E21+E17 -> 2601830.2 | F25: =+F21+F17 -> 2684206.1 | G25: =+G21+G17 -> 2889003.8 | H25: =+H21+H17 -> 3078201.2 | I25: =+I21+I17 -> 3260476.9 | J25: =+J21+J17 -> 3463285.7 | ... M25: =+M21+M17 -> 4001098.8 | N25: =SUM(C25:M25) -> 33735720
B26: % of Sales | C26: =C25/C7 -> 0.37825 | D26: =D25/D7 -> 0.37648765 | E26: =E25/E7 -> 0.40639915 | F26: =F25/F7 -> 0.39263739 | G26: =G25/G7 -> 0.39470103 | H26: =H25/H7 -> 0.39410508 | I26: =I25/I7 -> 0.38981578 | J26: =J25/J7 -> 0.38645845 | ... N26: =N25/N7 -> 0.38284381
B28: Other Income & Expense | C28: =+C7*C29 -> 112560 | D28: =+D4*D29 -> 97167.006 | E28: =+E4*E29 -> 116597.63 | F28: =+F4*F29 -> 139042.01 | G28: =+G4*G29 -> 124290.05 | H28: =+H4*H29 -> 113774.96 | I28: =+I4*I29 -> 123604.14 | J28: =+J4*J29 -> 131629.76 | K28: =+K4*K29 -> 190046.69 | ... M28: =+M4*M29 -> 199096.72 | N28: =SUM(C28:M28) -> 1540320.3
B29: % of Sales | C29: 0.0201 | D29: 0.0163 | E29: 0.0178 | F29: 0.02 | G29: 0.0168 | H29: 0.0145 | I29: 0.0148 | J29: 0.0148 | K29: 0.02 | L29: 0.0191 | M29: 0.0187 | N29: =N28/$N$7 -> 0.01748005
B31: Income Before Tax | C31: =+C7-C10-C25-C28 -> 1638840 | D31: =+D7-D10-D25-D28 -> 1789643.4 | E31: =+E7-E10-E25-E28 -> 1683881 | F31: =+F7-F10-F25-F28 -> 1856559 | G31: =+G7-G10-G25-G28 -> 2046764.2 | H31: =+H7-H10-H25-H28 -> 2216020.7 | I31: =+I7-I10-I25-I28 -> 2394402 | J31: =+J7-J10-J25-J28 -> 2635366.2 | ... M31: =+M7-M10-M25-M28 -> 3511662.4 | N31: =SUM(C31:M31) -> 25946652
B32: % of Sales | C32: =+C31/C7 -> 0.29265 | D32: =+D31/D7 -> 0.29901585 | E32: =+E31/E7 -> 0.26301786 | F32: =+F31/F7 -> 0.27157172 | G32: =+G31/G7 -> 0.27963271 | H32: =+H31/H7 -> 0.28371928 | I32: =+I31/I7 -> 0.28626968 | J32: =+J31/J7 -> 0.2940732 | ... N32: =+N31/N7 -> 0.29445096
B34: Tax | C34: =+C31*C35 -> 393321.6 | D34: =+D31*D35 -> 429514.41 | E34: =+E31*E35 -> 404131.43 | F34: =+F31*F35 -> 445574.15 | G34: =+G31*G35 -> 491223.41 | H34: =+H31*H35 -> 531844.98 | I34: =+I31*I35 -> 574656.48 | J34: =+J31*J35 -> 632487.88 | ... M34: =+M31*M35 -> 842798.97 | N34: =SUM(C34:M34) -> 6227196.5
B35: Effective Tax Rate | C35: 0.24 | D35: 0.24 | E35: 0.24 | F35: 0.24 | G35: 0.24 | H35: 0.24 | I35: 0.24 | J35: 0.24 | K35: 0.24 | L35: 0.24 | M35: 0.24 | N35: =N34/$N$31 -> 0.24
B37: Net Income | C37: =+C31-C34 -> 1245518.4 | D37: =+D31-D34 -> 1360129 | E37: =+E31-E34 -> 1279749.5 | F37: =+F31-F34 -> 1410984.8 | G37: =+G31-G34 -> 1555540.8 | H37: =+H31-H34 -> 1684175.8 | I37: =+I31-I34 -> 1819745.5 | J37: =+J31-J34 -> 2002878.3 | ... M37: =+M31-M34 -> 2668863.4 | N37: =SUM(C37:M37) -> 19719456
B38: % of Sales | C38: =+C37/C7 -> 0.222414 | D38: =+D37/D7 -> 0.22725205 | E38: =+E37/E7 -> 0.19989357 | F38: =+F37/F7 -> 0.20639451 | G38: =+G37/G7 -> 0.21252086 | H38: =+H37/H7 -> 0.21562666 | I38: =+I37/I7 -> 0.21756496 | J38: =+J37/J7 -> 0.22349563 | ... M38: =+M37/M7 -> 0.2442638 | N38: =N37/N7 -> 0.22378273

Sheet Statement of Cash Flows
B1: Johnson & Johnson University Case Competition
B2: Statement of Cash Flows
B4: *Financial statements are ficticious and not based on actual results
B5: $ in 000's | C5: Year 0 | D5: Year 1 | E5: Year 2 | F5: Year 3 | G5: Year 4 | H5: Year 5 | I5: Year 6 | J5: Year 7 | K5: Year 8 | L5: Year 9 | M5: Year 10 | N5: Cumu
B6: Net Income / (Loss) | C6: =+'Income Statement'!C37 -> 1245518.4 | D6: =+'Income Statement'!D37 -> 1360129 | E6: =+'Income Statement'!E37 -> 1279749.5 | F6: =+'Income Statement'!F37 -> 1410984.8 | G6: =+'Income Statement'!G37 -> 1555540.8 | H6: =+'Income Statement'!H37 -> 1684175.8 | I6: =+'Income Statement'!I37 -> 1819745.5 | J6: =+'Income Statement'!J37 -> 2002878.3 | ... M6: =+'Income Statement'!M37 -> 2668863.4 | N6: =SUM(C6:M6) -> 19719456
B8: Capital Expenditures | C8: =C$6*Levers!B57+IF('Decision Points'!$C$6="Base",0,0)+IF('Decision Points'!$C$6=Levers!A29,Levers!$D$29+(C6*0.1),0)+IF('Decision Points'!$C$6=Levers!$A$30,0,0)+IF('Decision Points'!$C$7="Base",0,0)+IF('Decision Points'!$C$7=Levers!$A$35,Levers!$D$35+(C6*0.1),0)+IF('Decision Points'!$C$7=Levers!$A$36,0,0) -> 211738.13 | D8: {=(D$6*Levers!C57)*(1+_xlfn.SWITCH('Decision Points'!$C$10,"Outsource",0,"Base",0,"New Plant Construction",'Supply Chain & Human Capital'!H17,"Plant Expansion",'Supply Chain & Human Capital'!H16))} -> 190418.05 | E8: {=(E$6*Levers!D57)*(1+_xlfn.SWITCH('Decision Points'!$C$10,"Outsource",0,"Base",0,"New Plant Construction",'Supply Chain & Human Capital'!I17,"Plant Expansion",'Supply Chain & Human Capital'!I16))} -> 179164.94 | F8: {=(F$6*Levers!E57)*(1+_xlfn.SWITCH('Decision Points'!$C$10,"Outsource",0,"Base",0,"New Plant Construction",'Supply Chain & Human Capital'!J17,"Plant Expansion",'Supply Chain & Human Capital'!J16))} -> 211647.72 | G8: {=(G$6*Levers!F57)*(1+_xlfn.SWITCH('Decision Points'!$C$10,"Outsource",0,"Base",0,"New Plant Construction",'Supply Chain & Human Capital'!K17,"Plant Expansion",'Supply Chain & Human Capital'!K16))} -> 264441.94 | H8: {=(H$6*Levers!G57)*(1+_xlfn.SWITCH('Decision Points'!$C$10,"Outsource",0,"Base",0,"New Plant Construction",'Supply Chain & Human Capital'!L17,"Plant Expansion",'Supply Chain & Human Capital'!L16))} -> 269468.12 | I8: {=I$6*Levers!H57*(1+_xlfn.SWITCH('Decision Points'!$C$10,"Outsource",0,"Base",0,"New Plant Construction",'Supply Chain & Human Capital'!L17,"Plant Expansion",'Supply Chain & Human Capital'!L16))} -> 254764.37 | J8: {=J$6*Levers!I57*(1+_xlfn.SWITCH('Decision Points'!$C$10,"Outsource",0,"Base",0,"New Plant Construction",'Supply Chain & Human Capital'!L17,"Plant Expansion",'Supply Chain & Human Capital'!L16))} -> 300431.74 | K8: {=K$6*Levers!J57*(1+_xlfn.SWITCH('Decision Points'!$C$10,"Outsource",0,"Base",0,"New Plant Construction",'Supply Chain & Human Capital'!L17,"Plant Expansion",'Supply Chain & Human Capital'!L16))} -> 309018.52 | L8: {=L$6*Levers!K57*(1+_xlfn.SWITCH('Decision Points'!$C$10,"Outsource",0,"Base",0,"New Plant Construction",'Supply Chain & Human Capital'!L17,"Plant Expansion",'Supply Chain & Human Capital'!L16))} -> 372689.26 | M8: {=M$6*Levers!L57*(1+_xlfn.SWITCH('Decision Points'!$C$10,"Outsource",0,"Base",0,"New Plant Construction",'Supply Chain & Human Capital'!L17,"Plant Expansion",'Supply Chain & Human Capital'!L16))} -> 453706.78 | N8: =SUM(C8:M8) -> 3017489.6
B10: Amortization / Depreciation | C10: =C$6*Levers!$B$58+IF('Decision Points'!$C$6="Base",0,0)+IF('Decision Points'!$C$6=Levers!$A$29,Levers!$E$29,0)+IF('Decision Points'!$C$6=Levers!$A$30,0,0)+IF('Decision Points'!$C$7="Base",0,0)+IF('Decision Points'!$C$7=Levers!$A$35,Levers!$E$35,0)+IF('Decision Points'!$C$7=Levers!$A$36,Levers!$D$36,0) -> 124551.84 | D10: =D$6*Levers!C58+IF('Decision Points'!$C$6="Base",0,0)+IF('Decision Points'!$C$6=Levers!A29,Levers!$E$29,0)+IF('Decision Points'!$C$6=Levers!$A$30,0,0)+IF('Decision Points'!$C$7="Base",0,0)+IF('Decision Points'!$C$7=Levers!$A$35,Levers!$E$35,0)+IF('Decision Points'!$C$7=Levers!$A$36,Levers!$D$36,0) -> 136012.9 | E10: =E$6*Levers!D58+IF('Decision Points'!$C$6="Base",0,0)+IF('Decision Points'!$C$6=Levers!A29,Levers!$E$29,0)+IF('Decision Points'!$C$6=Levers!$A$30,0,0)+IF('Decision Points'!$C$7="Base",0,0)+IF('Decision Points'!$C$7=Levers!$A$35,Levers!$E$35,0)+IF('Decision Points'!$C$7=Levers!$A$36,Levers!$D$36,0) -> 153569.95 | F10: =F$6*Levers!E58+IF('Decision Points'!$C$6="Base",0,0)+IF('Decision Points'!$C$6=Levers!A29,Levers!$E$29,0)+IF('Decision Points'!$C$6=Levers!$A$30,0,0)+IF('Decision Points'!$C$7="Base",0,0)+IF('Decision Points'!$C$7=Levers!$A$35,Levers!$E$35,0)+IF('Decision Points'!$C$7=Levers!$A$36,Levers!$D$36,0) -> 183428.03 | G10: =G$6*Levers!F58+IF('Decision Points'!$C$6="Base",0,0)+IF('Decision Points'!$C$6=Levers!A29,Levers!$E$29,0)+IF('Decision Points'!$C$6=Levers!$A$30,0,0)+IF('Decision Points'!$C$7="Base",0,0)+IF('Decision Points'!$C$7=Levers!$A$35,Levers!$E$35,0)+IF('Decision Points'!$C$7=Levers!$A$36,Levers!$D$36,0) -> 139998.67 | H10: =H$6*Levers!G58+IF('Decision Points'!$C$6="Base",0,0)+IF('Decision Points'!$C$6=Levers!A29,Levers!$E$29,0)+IF('Decision Points'!$C$6=Levers!$A$30,0,0)+IF('Decision Points'!$C$7="Base",0,0)+IF('Decision Points'!$C$7=Levers!$A$35,Levers!$E$35,0)+IF('Decision Points'!$C$7=Levers!$A$36,Levers!$D$36,0) -> 168417.58 | I10: =I$6*Levers!H58+IF('Decision Points'!$C$6="Base",0,0)+IF('Decision Points'!$C$6=Levers!A29,Levers!$E$29,0)+IF('Decision Points'!$C$6=Levers!$A$30,0,0)+IF('Decision Points'!$C$7="Base",0,0)+IF('Decision Points'!$C$7=Levers!$A$35,Levers!$E$35,0)+IF('Decision Points'!$C$7=Levers!$A$36,Levers!$D$36,0) -> 109184.73 | J10: =J$6*Levers!I58+IF('Decision Points'!$C$6="Base",0,0)+IF('Decision Points'!$C$6=Levers!A29,Levers!$E$29,0)+IF('Decision Points'!$C$6=Levers!$A$30,0,0)+IF('Decision Points'!$C$7="Base",0,0)+IF('Decision Points'!$C$7=Levers!$A$35,Levers!$E$35,0)+IF('Decision Points'!$C$7=Levers!$A$36,Levers!$D$36,0) -> 200287.83 | K10: =K$6*Levers!J58+IF('Decision Points'!$C$6="Base",0,0)+IF('Decision Points'!$C$6=Levers!A29,Levers!$E$29,0)+IF('Decision Points'!$C$6=Levers!$A$30,0,0)+IF('Decision Points'!$C$7="Base",0,0)+IF('Decision Points'!$C$7=Levers!$A$35,Levers!$E$35,0)+IF('Decision Points'!$C$7=Levers!$A$36,Levers!$D$36,0) -> 220727.52 | L10: =L$6*Levers!K58+IF('Decision Points'!$C$6="Base",0,0)+IF('Decision Points'!$C$6=Levers!A29,Levers!$E$29,0)+IF('Decision Points'!$C$6=Levers!$A$30,0,0)+IF('Decision Points'!$C$7="Base",0,0)+IF('Decision Points'!$C$7=Levers!$A$35,Levers!$E$35,0)+IF('Decision Points'!$C$7=Levers!$A$36,Levers!$D$36,0) -> 322997.36 | M10: =M$6*Levers!L58+IF('Decision Points'!$C$6="Base",0,0)+IF('Decision Points'!$C$6=Levers!A29,Levers!$E$29,0)+IF('Decision Points'!$C$6=Levers!$A$30,0,0)+IF('Decision Points'!$C$7="Base",0,0)+IF('Decision Points'!$C$7=Levers!$A$35,Levers!$E$35,0)+IF('Decision Points'!$C$7=Levers!$A$36,Levers!$D$36,0) -> 240197.71 | N10: =SUM(C10:M10) -> 1999374.1
B12: Working Capital
B14: Accounts Receivable | C14: =C$6*Levers!$B$59 -> -286469.23 | D14: =D$6*Levers!B59 -> -312829.66 | E14: =E$6*Levers!C59 -> -294342.4 | F14: =F$6*Levers!D59 -> -296306.81 | G14: =G$6*Levers!E59 -> -326663.57 | H14: =H$6*Levers!F59 -> -370518.67 | I14: =I$6*Levers!G59 -> -454936.38 | J14: =J$6*Levers!H59 -> -480690.79 | K14: =K$6*Levers!I59 -> -507673.29 | ... M14: =M$6*Levers!K59 -> -560461.31 | N14: =SUM(C14:M14) -> -4412657.1
B15: Inventory | C15: =C$6*Levers!B60 -> -361200.34 | D15: =D$6*Levers!B60 -> -394437.4 | E15: =E$6*Levers!C60 -> -371127.37 | F15: =F$6*Levers!D60 -> -409185.6 | G15: =G$6*Levers!E60 -> -388885.2 | H15: =H$6*Levers!F60 -> -471569.21 | I15: =I$6*Levers!G60 -> -509528.75 | J15: =J$6*Levers!H60 -> -480690.79 | K15: =K$6*Levers!I60 -> -529746.04 | ... M15: =M$6*Levers!K60 -> -613838.58 | N15: =SUM(C15:M15) -> -5101666.1
B16: Accounts Payable | C16: =C$6*Levers!B61 -> 199282.94 | D16: =D$6*Levers!B61 -> 217620.63 | E16: =E$6*Levers!C61 -> 217557.42 | F16: =F$6*Levers!D61 -> 225757.57 | G16: =G$6*Levers!E61 -> 233331.12 | H16: =H$6*Levers!F61 -> 269468.12 | I16: =I$6*Levers!G61 -> 291159.28 | J16: =J$6*Levers!H61 -> 320460.52 | K16: =K$6*Levers!I61 -> 331091.27 | ... M16: =M$6*Levers!K61 -> 453706.78 | N16: =SUM(C16:M16) -> 3181816.8
B18: Total Working Capital | C18: =SUM(C14:C16) -> -448386.62 | D18: =SUM(D14:D16) -> -489646.43 | E18: =SUM(E14:E16) -> -447912.34 | F18: =SUM(F14:F16) -> -479734.84 | G18: =SUM(G14:G16) -> -482217.65 | H18: =SUM(H14:H16) -> -572619.76 | I18: =SUM(I14:I16) -> -673305.85 | J18: =SUM(J14:J16) -> -640921.05 | ... M18: =SUM(M14:M16) -> -720593.12 | N18: =SUM(C18:M18) -> -6332506.4
B19: Change in Working Capital | C19: =C18--350000 -> -98386.624 | D19: =D18-C18 -> -41259.802 | E19: =E18-D18 -> 41734.085 | F19: =F18-E18 -> -31822.497 | G19: =G18-F18 -> -2482.8094 | H19: =H18-G18 -> -90402.11 | I19: =I18-H18 -> -100686.09 | J19: =J18-I18 -> 32384.796 | K19: =K18-J18 -> -65407.002 | ... M19: =M18-L18 -> -49752.452 | N19: =SUM(C19:M19) -> -370593.12
B21: Free Cash Flow | C21: =C6-C8+C10-C19 -> 1256718.7 | D21: =D6-D8+D10-D19 -> 1346983.6 | E21: =E6-E8+E10-E19 -> 1212420.5 | F21: =F6-F8+F10-F19 -> 1414587.6 | G21: =G6-G8+G10-G19 -> 1433580.3 | H21: =H6-H8+H10-H19 -> 1673527.3 | I21: =I6-I8+I10-I19 -> 1774852 | J21: =J6-J8+J10-J19 -> 1870349.6 | ... M21: =M6-M8+M10-M19 -> 2505106.8 | N21: =SUM(C21:M21) -> 19071933
B23: Discount Rate | C23: 0.07
C25: 0 | D25: 1 | E25: 2 | F25: 3 | G25: 4 | H25: 5 | I25: 6 | J25: 7 | K25: 8 | L25: 9 | M25: 10
B26: Discounted Cash Flow | C26: =C21/(1+$C$23)^C25 -> 1256718.7 | D26: =D21/(1+$C$23)^D25 -> 1258863.2 | E26: =E21/(1+$C$23)^E25 -> 1058975 | F26: =F21/(1+$C$23)^F25 -> 1154724.9 | G26: =G21/(1+$C$23)^G25 -> 1093671.6 | H26: =H21/(1+$C$23)^H25 -> 1193201.8 | I26: =I21/(1+$C$23)^I25 -> 1182658.8 | J26: =J21/(1+$C$23)^J25 -> 1164759.7 | ... M26: =M21/(1+$C$23)^M25 -> 1273469.3 | N26: =SUM(C26:M26) -> 13213502

Sheet Financial Highlights
B1: Johnson & Johnson University Case Competition
B2: Financial Highlights
B4: *Please note that all Financial Hightlights are subject to leveres activated on the "Decision Points" tab
B6: Highlights | F6: Selected Decision Points
B7: Financials | C7: Average | D7: Cumulative | F7: Decision Point | G7: Decision
B8: Net Sales | C8: =AVERAGE('Income Statement'!C7:M7) -> 8010795.9 | D8: =+'Income Statement'!N7 -> 88118755 | F8: R&D Strategy: | G8: ='Decision Points'!C5 -> Symmetrical: Base, Spiral: Base
F9: Symmetrical | G9: ='Decision Points'!C6 -> Base
B10: Gross Profit | C10: =AVERAGE('Income Statement'!C14:M14) -> 5565699.3 | D10: =+'Income Statement'!N14 -> 61222693 | F10: Spiral | G10: ='Decision Points'!C7 -> Base
B11: % NTS | C11: =AVERAGE('Income Statement'!C15:M15) -> 0.69368173 | D11: =D10/$D$8 -> 0.69477482 | F11: Pricing Strategy | G11: ='Decision Points'!C8 -> Base
F12: Marketing | G12: ='Decision Points'!C9 -> Silver
B13: OpEx | C13: =AVERAGE('Income Statement'!C25:M25) -> 3066883.7 | D13: =+'Income Statement'!N25 -> 33735720 | F13: Supply Chain | G13: ='Decision Points'!C10 -> Base
B14: % NTS | C14: =AVERAGE('Income Statement'!C26:M26) -> 0.38427869 | D14: =D13/$D$8 -> 0.38284381 | F14: Human Capital | G14: ='Decision Points'!C11 -> Base
F15: *these points are not available for selection; please return to the "Decision Points" tab
B16: Net Income | C16: =AVERAGE('Income Statement'!C37:M37) -> 1792677.8 | D16: =+'Income Statement'!N37 -> 19719456
B17: % NTS | C17: =AVERAGE('Income Statement'!C38:M38) -> 0.22184103 | D17: =D16/$D$8 -> 0.22378273
B19: Market Assumptions
B20: Market Growth | C20: =+Levers!B65 -> 0.075
B22: Market Share Metrics
B23: Beginning Share | C23: =+Levers!B68 -> 0.563576
B24: Ending Share | C24: =+Levers!L68 -> 0.53351553
B25: Peak Share | C25: =MAX(Levers!B68:L68) -> 0.563576
B26: Average Share | C26: =AVERAGE(Levers!B68:L68) -> 0.54909962
B28: Value Creation Metrics
B29: NPV | C29: ='Statement of Cash Flows'!N26 -> 13213502

Sheet Sandbox

Sheet BACKEND -->
A1: This tab is intentionally left blank

Sheet Levers
A1: Levers
A2: Decision Points & Options
A3: R&D Strategy: | B3: IP Both | C3: Internal Both | D3: Internal Symmetrical; IP Spiral | E3: IP Symmetrical; Internal Spiral | F3: Base
A4: symmetrical | B4: IP | C4: Internal | D4: Base
A5: Spiral | B5: IP | C5: Internal | D5: Base
A6: Pricing Strategy | B6: Low | C6: Med | D6: High | E6: Base
A7: Marketing | B7: Bronze | C7: Silver | D7: Gold | E7: Base
A8: Supply Chain | B8: Outsource | C8: Plant Expansion | D8: New Plant Construction | E8: Base
A9: Human Capital | B9: Full Time | C9: Contractor | D9: Base
A11: Income Statement Levers
A12: Pricing Strategy Sales increase | B12: Sales impact | C12: COGS impact | D12: GP Impact
A13: Low | B13: 0.003 | D13: =B13-C13 -> 0.003
A14: Medium | B14: 0.005 | D14: =B14-C14 -> 0.005
A15: High | B15: 0.01 | D15: =B15-C15 -> 0.01 | AN15: orginal equations
AO16: symetric base | AP16: symetric IP | AQ16: symetric internal | AR16: spiral base | AS16: spiral IP | AT16: spiral internal
A17: Marketing Strategy Sales increase | B17: Sales impact | AN17: year 1: | AO17: IF('Decision Points'!$C$6="Base",0,0) | AP17: IF('Decision Points'!$C$6=Levers!A29,Levers!$C$29,0) | AQ17: IF('Decision Points'!$C$6=Levers!$A$30,Levers!$C$30,0)*0.4 | AR17: IF('Decision Points'!$C$7="Base",0,0) | AS17: IF('Decision Points'!$C$7=Levers!$A$35,Levers!$C$35,0)*0 | AT17: IF('Decision Points'!$C$7=Levers!$A$36,Levers!$C$36,0)*0
A18: Bronze | B18: 0.002 | AN18: year 2 | AO18: IF('Decision Points'!$C$6="Base",0,0) | AP18: IF('Decision Points'!$C$6=Levers!A29,Levers!$C$29,0) | AQ18: IF('Decision Points'!$C$6=Levers!$A$30,Levers!$C$30,0)*0.6 | AR18: IF('Decision Points'!$C$7="Base",0,0) | AS18: IF('Decision Points'!$C$7=Levers!$A$35,Levers!$C$35,0)*0 | AT18: IF('Decision Points'!$C$7=Levers!$A$36,Levers!$C$36,0)*0
A19: Silver | B19: 0.0065 | AN19: year 3 | AO19: IF('Decision Points'!$C$6="Base",0,0) | AP19: IF('Decision Points'!$C$6=Levers!A29,Levers!$C$29,0) | AQ19: IF('Decision Points'!$C$6=Levers!$A$30,Levers!$C$30,0) | AR19: IF('Decision Points'!$C$7="Base",0,0) | AS19: IF('Decision Points'!$C$7=Levers!$A$35,Levers!$C$35,0)*0.6 | AT19: IF('Decision Points'!$C$7=Levers!$A$36,Levers!$C$36,0)*0.3
A20: Gold | B20: 0.00825 | AN20: year 4 | AO20: IF('Decision Points'!$C$6="Base",0,0) | AP20: IF('Decision Points'!$C$6=Levers!A29,Levers!$C$29,0) | AQ20: IF('Decision Points'!$C$6=Levers!$A$30,Levers!$C$30,0) | AR20: IF('Decision Points'!$C$7="Base",0,0) | AS20: IF('Decision Points'!$C$7=Levers!$A$35,Levers!$C$35,0)*0.8 | AT20: IF('Decision Points'!$C$7=Levers!$A$36,Levers!$C$36,0)*0.6
AN21: year 5 | AO21: IF('Decision Points'!$C$6="Base",0,0) | AP21: IF('Decision Points'!$C$6=Levers!A29,Levers!$C$29,0) | AQ21: IF('Decision Points'!$C$6=Levers!$A$30,Levers!$C$30,0) | AR21: IF('Decision Points'!$C$7="Base",0,0) | AS21: IF('Decision Points'!$C$7=Levers!$A$35,Levers!$C$35,0) | AT21: IF('Decision Points'!$C$7=Levers!$A$36,Levers!$C$36,0)
A22: Marketing SG&A expense increase
A23: Bronze | B23: 0.0015
A24: Silver | B24: 0.02
A25: Gold | B25: 0.03
A27: R&D Expense increase | AO27: C6 is symmetric, C7 is spiral
A28: symmetrical | B28: R&D expense impact | C28: sales impact | D28: capex exp (just impact IP options, year 1 impact) | E28: amortization/depreciation/write off? | AA28: jenna notes: | AO28: symetric base | AP28: symetric IP | AQ28: symetric internal | AR28: spiral base | AS28: spiral IP | AT28: spiral internal
A29: IP | B29: 0.01 | C29: 0.02 | D29: 200000 | E29: =D29/10 -> 20000 | F29: Lower GP ; Earlier FCF ( Spiral in 2012 launch ; Symmetrical 2014 - 2015 ) ; Immediate P&L Impact ; lowest R&D | G29: Shouldn’t we increase sales as a result? | AA29: sales offset by the cost of the IP (reoccuring licensing fee?) | AC29: spiral: | AG29: Product | AH29: R&D Strategy | AI29: Cash Flow | AJ29: Market Share | AN29: year 1: | AO29: =+IF('Decision Points'!$C$6="Base",0,0) | AP29: +IF('Decision Points'!$C$6=Levers!A29,Levers!$C$29,0)*0.75 | AQ29: +IF('Decision Points'!$C$6=Levers!$A$30,Levers!$C$30,0)*0 | AR29: +IF('Decision Points'!$C$7="Base",0,0) | AS29: +IF('Decision Points'!$C$7=Levers!$A$35,Levers!$C$35,0)*0 | AT29: +IF('Decision Points'!$C$7=Levers!$A$36,Levers!$C$36,0)*0.6
A30: Internal | B30: 0.04 | C30: 0.025 | D30: ` | F30: Higher GP ; Later FCF ( Spiral in 2012 launch ; Symmetrical 2014 - 2015 ) ; Immediate P&L Impact ; highest R&D | AA30: sym can hit market immediately (affects sales year 1), if developing internally impact hits year 2 40% and year 3 60% but fully imapct year 4 onwards | AO30: if spiral is base | AP30: if spiral is IP, 1% increase to sales, 40% impact of that so later to market | AQ30: if spiral is internal, 2.5% increase to sales | AR30: if symmetric is base, 0 impact | AS30: if symmetric is IP, 1% increase, 0 impact year one | AT30: if symmetric is internal, 2.5% increase, 0 impact year 1
A31: Internal Symmetrical; IP Spiral | F31: Lower GP in 2012 ; Earlier FCF ( Spiral in 2012 launch ) ; Higher GP in 2014 ; Later FCF ( Symmetrical 2014 - 2015 ) ; Immediate P&L Impact ; Low R&D impacts till Symmetrical Launch then flat | L31: Symmetrical has a larger TAM, spiral is new (IP Spiral will have a ) (JNJ can devolop spiral faster than competitors) | W31: or we can just do flat all around if easier? | AG31: Spiral | AH31: Purchase IP | AI31: More CapEx; Later to Market | AJ31: TBD | AP31: needs to be later to market | AQ31: earlier to market | AS31: earlier to market | AT31: later to market
A32: IP Symmetrical; Internal Spiral | F32: Higher GP in 2012 ; Later FCF ( Symmetrical 2014 - 2015 ) ; Lower GP in 2014 ; Earlier FCF ( Spiral in 2012 launch ) ; Immediate P&L Impact ; High R&D impacts till Symmetrical Launch then flat | H32: Higher GP for symmetrical (missing out , spiral can catch up )lower GP when compared to Spiral | W32: or we can just do flat all around if easier?
AH33: Internally Develop | AI33: More R&D; Earlier to Market | AJ33: TBD | AN33: year 2 | AO33: IF('Decision Points'!$C$6="Base",0,0) | AP33: IF('Decision Points'!$C$6=Levers!A29,Levers!$C$29,0) | AQ33: IF('Decision Points'!$C$6=Levers!$A$30,Levers!$C$30,0)*0 | AR33: IF('Decision Points'!$C$7="Base",0,0) | AS33: IF('Decision Points'!$C$7=Levers!$A$35,Levers!$C$35,0)*0.4 | AT33: IF('Decision Points'!$C$7=Levers!$A$36,Levers!$C$36,0)
A34: Spiral:
A35: IP | B35: 0.015 | C35: 0.01 | D35: 800000 | E35: =D35/10 -> 80000 | F35: Lower GP ; Earlier FCF ( Spiral in 2012 launch ; Symmetrical 2014 - 2015 ) ; Immediate P&L Impact ; lowest R&D | AA35: has a higher impact on sales because the technology is newer than symmetrical | AG35: Symmetrical | AH35: Purchase IP | AI35: More CapEx; Earlier to Market | AJ35: Higher | AN35: year 3 | AO35: IF('Decision Points'!$C$6="Base",0,0) | AP35: IF('Decision Points'!$C$6=Levers!A29,Levers!$C$29,0) | AQ35: IF('Decision Points'!$C$6=Levers!$A$30,Levers!$C$30,0)*.3 | AR35: IF('Decision Points'!$C$7="Base",0,0) | AS35: IF('Decision Points'!$C$7=Levers!$A$35,Levers!$C$35,0)*0.6 | AT35: IF('Decision Points'!$C$7=Levers!$A$36,Levers!$C$36,0)
A36: Internal | B36: 0.035 | C36: 0.025 | F36: Higher GP ; Later FCF ( Spiral in 2012 launch ; Symmetrical 2014 - 2015 ) ; Immediate P&L Impact ; highest R&D | AA36: would hit market later (affects sales year 2 if IP, year 3 if internal developed)
A37: Internal Symmetrical; IP Spiral | F37: Lower GP in 2012 ; Earlier FCF ( Spiral in 2012 launch ) ; Higher GP in 2014 ; Later FCF ( Symmetrical 2014 - 2015 ) ; Immediate P&L Impact ; Low R&D impacts till Symmetrical Launch then flat | AA37: internally developing spiral earlier to market than IP | AH37: Internally Develop | AI37: More R&D; Later to Market | AJ37: Lower | AN37: year 4 | AO37: IF('Decision Points'!$C$6="Base",0,0) | AP37: IF('Decision Points'!$C$6=Levers!A29,Levers!$C$29,0) | AQ37: IF('Decision Points'!$C$6=Levers!$A$30,Levers!$C$30,0)*.5 | AR37: IF('Decision Points'!$C$7="Base",0,0) | AS37: IF('Decision Points'!$C$7=Levers!$A$35,Levers!$C$35,0) | AT37: IF('Decision Points'!$C$7=Levers!$A$36,Levers!$C$36,0)
A38: IP Symmetrical; Internal Spiral | F38: Higher GP in 2012 ; Later FCF ( Symmetrical 2014 - 2015 ) ; Lower GP in 2014 ; Earlier FCF ( Spiral in 2012 launch ) ; Immediate P&L Impact ; High R&D impacts till Symmetrical Launch then flat
AN39: year 5 | AO39: IF('Decision Points'!$C$6="Base",0,0) | AP39: IF('Decision Points'!$C$6=Levers!A29,Levers!$C$29,0) | AQ39: IF('Decision Points'!$C$6=Levers!$A$30,Levers!$C$30,0)*0.75 | AR39: IF('Decision Points'!$C$7="Base",0,0) | AS39: IF('Decision Points'!$C$7=Levers!$A$35,Levers!$C$35,0) | AT39: IF('Decision Points'!$C$7=Levers!$A$36,Levers!$C$36,0)
A41: Supply chain expense increase | B41: COGS | C41: Sales impact
A42: Outsource | B42: 0.035 | D42: Immediate P&L impact | AP42: old version impact year one, new version impact started year 2 | AQ42: old version slight impact year 1 and 2, new version slight impact year 1, normal going forward | AS42: old version no impact to year 3, new version impact starting year 1 | AT42: no change, already later to market
A43: Plant Expansion | B43: -0.035 | D43: 3 years until operational, no P&L impact until 4th year, capex | E43: on P&L after a year | H43: increase in SG&A a little | K43: Should it be negative? | AO43: symetric base | AP43: symetric IP | AQ43: symetric internal | AR43: spiral base | AS43: spiral IP | AT43: spiral internal
...

Sheet Supply Chain & Human Capital
C4: Done | D4: Done | H4: COGS | U4: Sales
B5: Supply chain P&L | C5: COGS | D5: Sales impact | G5: Years till functional | H5: 1 | I5: 2 | J5: 3 | K5: 4 | L5: 5 | M5: 6 | N5: 7 | O5: 8 | P5: 9 | Q5: 10 | U5: 1 | V5: 2 | W5: 3 | X5: 4 | Y5: 5 | Z5: 6 | AA5: 7 | AB5: 8 | AC5: 9 | AD5: 10
B6: Outsource | C6: 0.035 | D6: 0.035 | G6: Outsource | H6: 0.052 | I6: 0.052 | J6: 0.052 | K6: 0.052 | L6: 0.052 | M6: 0.052 | N6: 0.052 | O6: 0.052 | P6: 0.052 | Q6: 0.052 | U6: 0.035 | V6: 0.035 | W6: 0.035 | X6: 0.035 | Y6: 0.035 | Z6: 0.035 | AA6: 0.035 | AB6: 0.035 | AC6: 0.035 | AD6: 0.035
B7: Plant Expansion | C7: -0.025 | D7: 0.03 | G7: Plant Expansion | H7: =$C$7*70% -> -0.0175 | I7: =$C$7*100% -> -0.025 | J7: =$C$7*100% -> -0.025 | K7: =$C$7*100% -> -0.025 | L7: =$C$7*100% -> -0.025 | M7: =$C$7*100% -> -0.025 | N7: =$C$7*100% -> -0.025 | O7: =$C$7*100% -> -0.025 | P7: =$C$7*100% -> -0.025 | Q7: =$C$7*100% -> -0.025 | S7: 70100 | U7: =$D$7*70% -> 0.021 | V7: =$D$7*100% -> 0.03 | W7: =$D$7*100% -> 0.03 | X7: =$D$7*100% -> 0.03 | Y7: =$D$7*100% -> 0.03 | Z7: =$D$7*100% -> 0.03 | AA7: =$D$7*100% -> 0.03 | AB7: =$D$7*100% -> 0.03 | AC7: =$D$7*100% -> 0.03 | AD7: =$D$7*100% -> 0.03
B8: New Plant Construction | C8: -0.035 | D8: 0.06 | G8: New Plant Construction | H8: =$C$8*60% -> -0.021 | I8: =$C$8*80% -> -0.028 | J8: =$C$8*100% -> -0.035 | K8: =$C$8*100% -> -0.035 | L8: =$C$8*100% -> -0.035 | M8: =$C$8*100% -> -0.035 | N8: =$C$8*100% -> -0.035 | O8: =$C$8*100% -> -0.035 | P8: =$C$8*100% -> -0.035 | Q8: =$C$8*100% -> -0.035 | S8: 60,80,100 | U8: =$D$8*60% -> 0.036 | V8: =$D$8*80% -> 0.048 | W8: 0.06 | X8: 0.06 | Y8: 0.06 | Z8: 0.06 | AA8: 0.06 | AB8: 0.06 | AC8: 0.06 | AD8: 0.06
B10: Human Capital expense increase | C10: Done | D10: GP impact | E10: GP Impact (in cogs line) | H10: 1 | I10: 2 | J10: 3 | K10: 4 | L10: 5 | M10: 6 | N10: 7 | O10: 8 | P10: 9 | Q10: 10
B11: Contractor | C11: 0.06 | E11: 0 | H11: 0.04 | I11: 0.06 | J11: 0.06 | K11: 0.06 | L11: 0.06 | M11: 0.06 | N11: 0.06 | O11: 0.06 | P11: 0.06 | Q11: 0.06 | S11: effencies in GP for full-time by increasing sales slightly (8-10) due to high turnover
B12: Full-time | C12: 0.1 | E12: 0.01 | H12: 0.07 | I12: 0.1 | J12: 0.1 | K12: 0.1 | L12: 0.1 | M12: 0.1 | N12: 0.1 | O12: 0.09 | P12: 0.08 | Q12: 0.08 | S12: Should we add GP increase for full-time employees in years 4-10?
E13: 0.02
B14: Supply chain capex increase | H14: 1 | I14: 2 | J14: 3 | K14: 4 | L14: 5 | M14: 6 | N14: 7 | O14: 8 | P14: 9 | Q14: 10
B15: Outsource | C15: 0 | H15: 0 | I15: 0 | J15: 0 | K15: 0 | L15: 0 | M15: 0 | N15: 0 | O15: 0 | P15: 0 | Q15: 0
B16: Plant Expansion | C16: 0.25 | H16: =$C$16*100% -> 0.25 | I16: =$C$16*100% -> 0.25 | J16: 0 | K16: 0 | L16: 0 | M16: 0 | N16: 0 | O16: 0 | P16: 0 | Q16: 0
B17: New Plant Construction | C17: 0.35 | H17: =$C$17*100% -> 0.35 | I17: =$C$17*100% -> 0.35 | J17: =$C$17*100% -> 0.35 | K17: 0 | L17: 0 | M17: 0 | N17: 0 | O17: 0 | P17: 0 | Q17: 0
B20: SG&A fixed operating costs | H20: 1 | I20: 2 | J20: 3 | K20: 4 | L20: 5 | M20: 6 | N20: 7 | O20: 8 | P20: 9 | Q20: 10
B21: Outsource | H21: 0 | I21: 0 | J21: 0 | K21: 0 | L21: 0 | M21: 0 | N21: 0 | O21: 0 | P21: 0 | Q21: 0
B22: Plant Expansion | H22: 0.0025 | I22: 0.005 | J22: 0.005 | K22: 0.005 | L22: 0.005 | M22: 0.005 | N22: 0.005 | O22: 0.005 | P22: 0.005 | Q22: 0.005 | S22: 70100
B23: New Plant Construction | H23: 0.003 | I23: 0.007 | J23: 0.01 | K23: 0.01 | L23: 0.01 | M23: 0.01 | N23: 0.01 | O23: 0.01 | P23: 0.01 | Q23: 0.01 | S23: 60,80,100

Sheet Feedback
B1: Feedback | D1: How we addressed
A2: Excel
A3: *Note when stress testing specific decision points, all other decision points were kept at base
A4: General:
B5: Please stress test the decision points to confirm they make logical sense based on the story you are trying to relay. Some of the decision points don’t have the same impact on financials as it is communicated they would based on the write-up document | D5: see stress testing columns, our team to stress test
B6: Ethicon sales were ~$6.5B in 2012, ~$4.4B seems like a low baseline. Where is market share/growth information from in the support tab? Coordinate with write-up that we feel good about the assumptions | D6: 5.8 starting point
B7: There seems to be no clear relationship between the various decision points, with most decision points being mutually exclusive. For example, if students select high pricing and high marketing, would expect the GP/NI margins to increase (with potential for some negative NI margin impact, depending on how expensive the marketing is). Consider decision points having variable impacts on GP/NI margins through multiple peglines (not strictly flat increase in sales, having the same proportional increase in COGS) | D7: added more impacts to decisions points in levers background
B8: Why does the GP and NI margin decrease throughout the launch of stratafix? Do we have evidence that Startafix erodes margins? | D8: adjusted baseline
B9: Specify that Marketing falls under SG&A. Its not super clear where the costs sits in the P&L (catering to students, sometimes not always finance majors as well) | D9: noted in line item title
B10: Bolden or make clear the totals peglines (GP, OPEX, IBT, NI) | D10: bolded lines
B11: Update J&J logos and colors in model. Can leverage PY models for reference
B12: Input a decision points summary on the financial highlights tab, similar to PY models | D12: added
A13: R&D Decision Point:
B14: Is there different R&D costs associated with internal development or IP of symmetrical/spiral. Does one cost more to develop than the other? Does one take longer to develop than the other? They seem to cost the same and be on the exact same timeline right now | D14: Spiral costs more to develop and purchase IP as the technology is more complex than symmetrical which already exists, costs increased for Spiral
B15: Theres no impact on sales based on internal/external R&D… work with the write-up team to determine which R&D implications take place and how material they are to Sales/COGS.etc. Does the company maybe save cost on one strategy vs. the other? If one were to internally develop vs. buy IP, would assume theres a lag in timing for when there is an increase in sales. Whatever decisions are made should be communicated to the write-up team to ensure its captured in the case | D15: if symmetrical is internally developed has 40% impact on sales Year 1 and 60% year 2 and full impact year 3. Symmetric Internal 100% immediate impact if spiral is internally developed no impact year 1 and 2, 30% impact year 3, 60% year 4, full impact year 5 onward. If spiral IP is bought no impact year 1 and 2, 60% impact year 3, 80% year 4, full imapct year 5 onwards
A16: Pricing Decision Point:
B17: Would not expect GP to stay flat as pricing decisions change. As price increases, usually so does GP… maybe build in a volume and price lever in the backend of the model to be able to view Sales/COGS a bit deeper. PY models have this built in (unlocked versions) | D17: This has been fixed, adjusted GP line formulas to remain the same for base but now able to add % impact without throwing off anything
A18: Supply Chain Decision Point:
B19: Why is a new plant construction cheaper than a plant extension? Would think there are additional costs to a new plant
B20: Consider other pegline impacts when building new plant vs. expansion vs. outsourcing… are there impacts on sales depending on when we can begin manufacturing the product (based on the write-up, outsourcing manufacturing has an accelerated impact on sales, while plant modifications takes a few years)? Can we have GP efficiencies because of better skilled workers or new equipment? Are there additional costs or savings to other peglines based on what the student selects (ex. higher SG&A costs associated with a new plant)
A21: Human Capital Decision Point:
B22: Why are contractors more expensive than FTEs? FTEs have additional costs associated with them (benefits, fringe, etc.)
B24: put cash flow on a new tab
B26: check the sales %
