Workbook

Sheet Cover & Summary
A1: PHILADELPHIA PGA SECTION
A2: Growth Strategy Financial Model — Investment Committee Overview
A3: "We Built the Game. It's Time Philadelphia Knew It."
A5: REVENUE SUMMARY BY YEAR
B6: Year 1 | C6: Year 2 | D6: Year 3 | E6: Year 4 | F6: Year 5 | G6: Year 6 | H6: Year 7 | I6: Year 8 | J6: Year 9 | K6: Year 10
A7: Platform Revenue | B7: ='Revenue Build'!B20 -> 265097.45 | C7: ='Revenue Build'!C20 -> 460846.94 | D7: ='Revenue Build'!D20 -> 768382.19 | E7: ='Revenue Build'!E20 -> 1000032.2 | F7: ='Revenue Build'!F20 -> 1352494.4 | G7: ='Revenue Build'!G20 -> 1503162.3 | H7: ='Revenue Build'!H20 -> 1665684 | I7: ='Revenue Build'!I20 -> 1832755.8 | ... K7: ='Revenue Build'!K20 -> 2066507
A8: Creator Revenue | B8: ='Revenue Build'!B38 -> 979.2 | C8: ='Revenue Build'!C38 -> 1815.4368 | D8: ='Revenue Build'!D38 -> 63116.5 | E8: ='Revenue Build'!E38 -> 118065.99 | F8: ='Revenue Build'!F38 -> 205510.49 | G8: ='Revenue Build'!G38 -> 281243.39 | H8: ='Revenue Build'!H38 -> 367015.3 | I8: ='Revenue Build'!I38 -> 462827.9 | ... K8: ='Revenue Build'!K38 -> 708943.44
A9: Venue Revenue | B9: ='Revenue Build'!B56 -> 131224 | C9: ='Revenue Build'!C56 -> 196891.08 | D9: ='Revenue Build'!D56 -> 328246.35 | E9: ='Revenue Build'!E56 -> 394012.49 | F9: ='Revenue Build'!F56 -> 525510.49 | G9: ='Revenue Build'!G56 -> 525675.81 | H9: ='Revenue Build'!H56 -> 525846.08 | I9: ='Revenue Build'!I56 -> 526021.46 | ... K9: ='Revenue Build'!K56 -> 526388.17
A10: Corporate Revenue | B10: ='Revenue Build'!B71 -> 187500 | C10: ='Revenue Build'!C71 -> 546000 | D10: ='Revenue Build'!D71 -> 910000 | E10: ='Revenue Build'!E71 -> 1365000 | F10: ='Revenue Build'!F71 -> 2047500 | G10: ='Revenue Build'!G71 -> 2366000 | H10: ='Revenue Build'!H71 -> 2639000 | I10: ='Revenue Build'!I71 -> 2957500 | ... K10: ='Revenue Build'!K71 -> 3640000
A11: TOTAL REVENUE | B11: ='Revenue Build'!B78 -> 584800.65 | C11: ='Revenue Build'!C78 -> 1205553.5 | D11: ='Revenue Build'!D78 -> 2069745 | E11: ='Revenue Build'!E78 -> 2877110.7 | F11: ='Revenue Build'!F78 -> 4131015.4 | G11: ='Revenue Build'!G78 -> 4676081.5 | H11: ='Revenue Build'!H78 -> 5197545.4 | I11: ='Revenue Build'!I78 -> 5779105.2 | ... K11: ='Revenue Build'!K78 -> 6941838.6
A13: EBITDA | B13: ='Margin Analysis'!B47 -> -715646.6 | C13: ='Margin Analysis'!C47 -> -651336.82 | D13: ='Margin Analysis'!D47 -> -219866.69 | E13: ='Margin Analysis'!E47 -> -5610.34 | F13: ='Margin Analysis'!F47 -> 652175.49 | G13: ='Margin Analysis'!G47 -> 911168.83 | H13: ='Margin Analysis'!H47 -> 954215.76 | I13: ='Margin Analysis'!I47 -> 1235087.3 | ... K13: ='Margin Analysis'!K47 -> 1609199.4
A14: EBITDA Margin % | B14: ='Margin Analysis'!B48 -> -1.2237445 | C14: ='Margin Analysis'!C48 -> -0.54028033 | D14: ='Margin Analysis'!D48 -> -0.10622888 | E14: ='Margin Analysis'!E48 -> -0.001949991 | F14: ='Margin Analysis'!F48 -> 0.15787292 | G14: ='Margin Analysis'!G48 -> 0.19485735 | H14: ='Margin Analysis'!H48 -> 0.18358969 | I14: ='Margin Analysis'!I48 -> 0.21371601 | ... K14: ='Margin Analysis'!K48 -> 0.2318117
A15: Free Cash Flow | B15: ='Margin Analysis'!B59 -> -791670.69 | C15: ='Margin Analysis'!C59 -> -761274.72 | D15: ='Margin Analysis'!D59 -> -392489.27 | E15: ='Margin Analysis'!E59 -> -214055.12 | F15: ='Margin Analysis'!F59 -> 213251.08 | G15: ='Margin Analysis'!G59 -> 441037.87 | H15: ='Margin Analysis'!H59 -> 453049.04 | I15: ='Margin Analysis'!I59 -> 634178.73 | ... K15: ='Margin Analysis'!K59 -> 859548.95
A16: FCF Margin % | B16: ='Margin Analysis'!B60 -> -1.3537445 | C16: ='Margin Analysis'!C60 -> -0.63147322 | D16: ='Margin Analysis'!D60 -> -0.1896317 | E16: ='Margin Analysis'!E60 -> -0.074399336 | F16: ='Margin Analysis'!F60 -> 0.051621952 | G16: ='Margin Analysis'!G60 -> 0.094317832 | H16: ='Margin Analysis'!H60 -> 0.087165961 | I16: ='Margin Analysis'!I60 -> 0.10973649 | ... K16: ='Margin Analysis'!K60 -> 0.12382151
A18: VALUATION & INVESTMENT RETURNS
A19: DCF Enterprise Value (Perpetuity Growth) | B19: ='DCF Valuation'!B43 -> 1245555.5
A20: DCF Enterprise Value (Exit Multiple) | B20: ='DCF Valuation'!B44 -> 4195111.3
A21: DCF Enterprise Value (Average) | B21: ='DCF Valuation'!B45 -> 2720333.4
A22: LBO Sponsor MOIC | B22: ='LBO Analysis'!B53 -> 5.2400756
A23: LBO Sponsor IRR (5-yr hold) | B23: ='LBO Analysis'!B54 -> 0.39273186
A24: EV / Year 5 EBITDA | B24: ='DCF Valuation'!B51 -> 4.1711678
A25: EV / Year 10 EBITDA | B25: ='DCF Valuation'!B52 -> 1.6904886
A27: KEY OPERATING KPIs — YEAR 5 SNAPSHOT
A28: Active Pros on Platform | B28: ='Revenue Build'!F9 -> 286.65
A29: Total Annual Lesson Bookings | B29: ='Revenue Build'!F12 -> 100900.8
A30: Gross Marketplace Volume | B30: ='Revenue Build'!F14 -> 9653002.8
A31: Active Creators | B31: ='Revenue Build'!F23 -> 50
A32: Active Venue Partners | B32: ='Revenue Build'!F41 -> 8
A33: Active Corporate Clients | B33: ='Revenue Build'!F59 -> 45
A34: Consumer LTV / CAC | B34: ='Unit Economics'!F14 -> 10.723359
A35: Corporate LTV / CAC | B35: ='Unit Economics'!F43 -> 91
A37: SCENARIO COMPARISON — YEAR 5 EBITDA & VALUATION
B38: Base | C38: Upside | D38: Downside | E38: Stress
A39: Year 5 EBITDA | B39: ='Scenario Analysis'!B34 -> 652175.49 | C39: ='Scenario Analysis'!C34 -> 1619358 | D39: ='Scenario Analysis'!D34 -> 123930.46 | E39: ='Scenario Analysis'!E34 -> -144585.54
A40: Implied EV | B40: ='Scenario Analysis'!B35 -> 7826105.8 | C40: ='Scenario Analysis'!C35 -> 22671013 | D40: ='Scenario Analysis'!D35 -> 991443.7 | E40: ='Scenario Analysis'!E35 -> 0
A41: LBO IRR | B41: ='Scenario Analysis'!B37 -> 0.28 | C41: ='Scenario Analysis'!C37 -> 0.42 | D41: ='Scenario Analysis'!D37 -> 0.05 | E41: ='Scenario Analysis'!E37 -> -0.15
A43: INVESTMENT THESIS — KEY TAKEAWAYS
A44: BIGGEST VALUE DRIVERS: Platform transaction revenue scales with pro onboarding; corporate program offers highest absolute $ per client; venue partnerships provide low-CAC top-of-funnel.
A45: MOST IMPORTANT RISKS: Pro adoption speed is the critical gate; brand confusion with PGA Tour must be addressed before marketing spend scales; corporate sales cycle length determines cash flow timing.
A46: MARGIN INFLECTION POINTS: Y2-3 transition from investment to contribution-positive; Y5 operating leverage kicks in as fixed costs are absorbed; Y7+ mature margins approach 25-35% EBITDA.
...

Sheet Assumptions
A1: PHILADELPHIA PGA SECTION — MASTER ASSUMPTIONS
A3: A. MARKET & DEMAND ASSUMPTIONS
A4: Assumption | B4: Value | C4: Unit | D4: Notes / Source
A5: Total PGA Professionals in Phila Section | B5: 900 | C5: # | D5: Per Philadelphia PGA brief
A6: % of Pros Addressable — Platform | B6: 0.7 | C6: % | D6: Excludes retired / inactive
A7: % of Pros Addressable — Creator | B7: 0.05 | C7: % | D7: Top content-capable pros
A8: Total Golfer Population in Region | B8: 2000000 | C8: # | D8: 2M+ rounds managed annually
A9: Beginner / Casual Golfer Population | B9: 500000 | C9: # | D9: ~25% of total golfer base
A10: Annual Golf Participation Growth | B10: 0.03 | C10: % | D10: National avg ~3% post-COVID
A11: Corporate Prospects in Phila DMA | B11: 200 | C11: # | D11: Finance, law, healthcare, tech
A12: Venue Partnership Prospects | B12: 8 | C12: # | D12: Topgolf + regional off-course
A13: Regional Golf Spending ($M) | B13: 200 | C13: $M | D13: Per brief — $200M+
A14: Phila DMA Households | B14: 2900000 | C14: # | D14: Census estimate
A15: % HH with Golf Interest | B15: 0.08 | C15: % | D15: National avg ~7-9%
A16: Non-Golfers Interested Nationally | B16: 21000000 | C16: # | D16: Per NGF data
A17: Phila DMA Share of National Pool | B17: 0.025 | C17: % | D17: ~2.5% of national pop
A19: B. LEARN GOLF PLATFORM ASSUMPTIONS
A20: Assumption | B20: Value | C20: Unit | D20: Notes / Source
A21: Year 1 Pro Onboarding Rate | B21: 0.15 | C21: % | D21: Conservative — 15% of addressable
A22: Year 3 Pro Onboarding Rate | B22: 0.4 | C22: % | D22: Mid-maturity target
A23: Year 5 Pro Onboarding Rate | B23: 0.65 | C23: % | D23: Scale target
A24: Year 10 Pro Onboarding Rate | B24: 0.85 | C24: % | D24: Mature platform
A25: Active Pro Rate (% of onboarded) | B25: 0.7 | C25: % | D25: Pros actively taking bookings
A26: Lessons per Active Pro per Week | B26: 8 | C26: #/wk | D26: Avg across all active pros
A27: Avg Lesson Price ($) | B27: 85 | C27: $ | D27: Phila market avg
A28: Annual Lesson Price Escalation | B28: 0.03 | C28: % | D28: Inflation + quality premium
A29: Platform Take Rate | B29: 0.12 | C29: % | D29: 12% of gross lesson value
A30: Premium Listing Price ($/month) | B30: 99 | C30: $/mo | D30: Enhanced profile + visibility
A31: % of Active Pros Buying Premium | B31: 0.25 | C31: % | D31: Year 1 estimate
A32: Lesson Package Attach Rate | B32: 0.15 | C32: % | D32: % of lessons as bundles
... A35: Teaching Weeks per Year | B35: 44 | C35: wks | D35: Excludes holidays / weather
A37: C. CREATOR NETWORK ASSUMPTIONS
A38: Assumption | B38: Value | C38: Unit | D38: Notes / Source
A39: Year 1 Creators Onboarded | B39: 10 | C39: # | D39: Pilot cohort of top pros
A40: Year 3 Creators Active | B40: 30 | C40: # | D40: Expanded network
A41: Year 5 Creators Active | B41: 50 | C41: # | D41: Mature creator program
A42: Avg Monthly Impressions per Creator | B42: 50000 | C42: # | D42: Social media reach
A43: Engagement Rate | B43: 0.04 | C43: % | D43: Industry avg 3-5% for niche
A44: Clickthrough Rate (to website) | B44: 0.02 | C44: % | D44: Standard social CTR
A45: Conversion Rate — Click to Inquiry | B45: 0.08 | C45: % | D45: Landing page conversion
...

Sheet Revenue Build
A1: REVENUE BUILD BY SEGMENT — 10 YEAR FORECAST
B2: Year 1 | C2: Year 2 | D2: Year 3 | E2: Year 4 | F2: Year 5 | G2: Year 6 | H2: Year 7 | I2: Year 8 | J2: Year 9 | K2: Year 10
A4: A. LEARN GOLF PLATFORM
A5: Total Addressable Pros | B5: =Assumptions!B5*Assumptions!B6 -> 630 | C5: =Assumptions!B5*Assumptions!B6 -> 630 | D5: =Assumptions!B5*Assumptions!B6 -> 630 | E5: =Assumptions!B5*Assumptions!B6 -> 630 | F5: =Assumptions!B5*Assumptions!B6 -> 630 | G5: =Assumptions!B5*Assumptions!B6 -> 630 | H5: =Assumptions!B5*Assumptions!B6 -> 630 | I5: =Assumptions!B5*Assumptions!B6 -> 630 | J5: =Assumptions!B5*Assumptions!B6 -> 630 | K5: =Assumptions!B5*Assumptions!B6 -> 630
A6: Pro Onboarding Rate | B6: 0.15 | C6: 0.25 | D6: 0.4 | E6: 0.5 | F6: 0.65 | G6: 0.7 | H6: 0.75 | I6: 0.8 | J6: 0.82 | K6: 0.85
A7: Onboarded Pros | B7: =B5*B6 -> 94.5 | C7: =C5*C6 -> 157.5 | D7: =D5*D6 -> 252 | E7: =E5*E6 -> 315 | F7: =F5*F6 -> 409.5 | G7: =G5*G6 -> 441 | H7: =H5*H6 -> 472.5 | I7: =I5*I6 -> 504 | ... K7: =K5*K6 -> 535.5
A8: Active Pro Rate | B8: =Assumptions!B25 -> 0.7 | C8: =Assumptions!B25 -> 0.7 | D8: =Assumptions!B25 -> 0.7 | E8: =Assumptions!B25 -> 0.7 | F8: =Assumptions!B25 -> 0.7 | G8: =Assumptions!B25 -> 0.7 | H8: =Assumptions!B25 -> 0.7 | I8: =Assumptions!B25 -> 0.7 | J8: =Assumptions!B25 -> 0.7 | K8: =Assumptions!B25 -> 0.7
A9: Active Pros | B9: =B7*B8 -> 66.15 | C9: =C7*C8 -> 110.25 | D9: =D7*D8 -> 176.4 | E9: =E7*E8 -> 220.5 | F9: =F7*F8 -> 286.65 | G9: =G7*G8 -> 308.7 | H9: =H7*H8 -> 330.75 | I9: =I7*I8 -> 352.8 | ... K9: =K7*K8 -> 374.85
A10: Lessons per Pro per Week | B10: =Assumptions!B26 -> 8 | C10: =Assumptions!B26 -> 8 | D10: =Assumptions!B26 -> 8 | E10: =Assumptions!B26 -> 8 | F10: =Assumptions!B26 -> 8 | G10: =Assumptions!B26 -> 8 | H10: =Assumptions!B26 -> 8 | I10: =Assumptions!B26 -> 8 | J10: =Assumptions!B26 -> 8 | K10: =Assumptions!B26 -> 8
A11: Teaching Weeks per Year | B11: =Assumptions!B35 -> 44 | C11: =Assumptions!B35 -> 44 | D11: =Assumptions!B35 -> 44 | E11: =Assumptions!B35 -> 44 | F11: =Assumptions!B35 -> 44 | G11: =Assumptions!B35 -> 44 | H11: =Assumptions!B35 -> 44 | I11: =Assumptions!B35 -> 44 | J11: =Assumptions!B35 -> 44 | K11: =Assumptions!B35 -> 44
A12: Total Annual Lessons | B12: =B9*B10*B11 -> 23284.8 | C12: =C9*C10*C11 -> 38808 | D12: =D9*D10*D11 -> 62092.8 | E12: =E9*E10*E11 -> 77616 | F12: =F9*F10*F11 -> 100900.8 | G12: =G9*G10*G11 -> 108662.4 | H12: =H9*H10*H11 -> 116424 | I12: =I9*I10*I11 -> 124185.6 | ... K12: =K9*K10*K11 -> 131947.2
A13: Avg Lesson Price ($) | B13: =Assumptions!B27 -> 85 | C13: =B13*(1+Assumptions!B28) -> 87.55 | D13: =C13*(1+Assumptions!B28) -> 90.1765 | E13: =D13*(1+Assumptions!B28) -> 92.881795 | F13: =E13*(1+Assumptions!B28) -> 95.668249 | G13: =F13*(1+Assumptions!B28) -> 98.538296 | H13: =G13*(1+Assumptions!B28) -> 101.49445 | I13: =H13*(1+Assumptions!B28) -> 104.53928 | J13: =I13*(1+Assumptions!B28) -> 107.67546 | K13: =J13*(1+Assumptions!B28) -> 110.90572
A14: Gross Marketplace Volume ($) | B14: =B12*B13 -> 1979208 | C14: =C12*C13 -> 3397640.4 | D14: =D12*D13 -> 5599311.4 | E14: =E12*E13 -> 7209113.4 | F14: =F12*F13 -> 9653002.8 | G14: =G12*G13 -> 10707408 | H14: =H12*H13 -> 11816389 | I14: =I12*I13 -> 12982273 | ... K14: =K12*K13 -> 14633699
A15: Platform Take Rate | B15: =Assumptions!B29 -> 0.12 | C15: =Assumptions!B29 -> 0.12 | D15: =Assumptions!B29 -> 0.12 | E15: =Assumptions!B29 -> 0.12 | F15: =Assumptions!B29 -> 0.12 | G15: =Assumptions!B29 -> 0.12 | H15: =Assumptions!B29 -> 0.12 | I15: =Assumptions!B29 -> 0.12 | J15: =Assumptions!B29 -> 0.12 | K15: =Assumptions!B29 -> 0.12
A16: Transaction Revenue ($) | B16: =B14*B15 -> 237504.96 | C16: =C14*C15 -> 407716.85 | D16: =D14*D15 -> 671917.37 | E16: =E14*E15 -> 865093.61 | F16: =F14*F15 -> 1158360.3 | G16: =G14*G15 -> 1284888.9 | H16: =H14*H15 -> 1417966.7 | I16: =I14*I15 -> 1557872.8 | ... K16: =K14*K15 -> 1756043.9
A17: Active Pros on Premium | B17: 0.2 | C17: 0.25 | D17: 0.3 | E17: 0.35 | F17: 0.4 | G17: 0.42 | H17: 0.45 | I17: 0.47 | J17: 0.48 | K17: 0.5
A18: Premium Listing Revenue ($) | B18: =B9*B17*Assumptions!B30*12 -> 15717.24 | C18: =C9*C17*Assumptions!B30*12 -> 32744.25 | D18: =D9*D17*Assumptions!B30*12 -> 62868.96 | E18: =E9*E17*Assumptions!B30*12 -> 91683.9 | F18: =F9*F17*Assumptions!B30*12 -> 136216.08 | G18: =G9*G17*Assumptions!B30*12 -> 154028.95 | H18: =H9*H17*Assumptions!B30*12 -> 176818.95 | I18: =I9*I17*Assumptions!B30*12 -> 196989.41 | J18: =J9*J17*Assumptions!B30*12 -> 206210.19 | K18: =K9*K17*Assumptions!B30*12 -> 222660.9
A19: Bundle Attach Uplift ($) | B19: =B16*Assumptions!B34 -> 11875.248 | C19: =C16*Assumptions!B34 -> 20385.842 | D19: =D16*Assumptions!B34 -> 33595.868 | E19: =E16*Assumptions!B34 -> 43254.68 | F19: =F16*Assumptions!B34 -> 57918.017 | G19: =G16*Assumptions!B34 -> 64244.447 | H19: =H16*Assumptions!B34 -> 70898.336 | I19: =I16*Assumptions!B34 -> 77893.638 | J19: =J16*Assumptions!B34 -> 82236.209 | K19: =K16*Assumptions!B34 -> 87802.196
A20: TOTAL PLATFORM REVENUE ($) | B20: =B16+B18+B19 -> 265097.45 | C20: =C16+C18+C19 -> 460846.94 | D20: =D16+D18+D19 -> 768382.19 | E20: =E16+E18+E19 -> 1000032.2 | F20: =F16+F18+F19 -> 1352494.4 | G20: =G16+G18+G19 -> 1503162.3 | H20: =H16+H18+H19 -> 1665684 | I20: =I16+I18+I19 -> 1832755.8 | ... K20: =K16+K18+K19 -> 2066507
A22: B. CREATOR / INFLUENCER NETWORK
A23: Active Creators | B23: 10 | C23: 18 | D23: 30 | E23: 38 | F23: 50 | G23: 55 | H23: 60 | I23: 65 | J23: 68 | K23: 70
A24: Avg Monthly Impressions per Creator | B24: =Assumptions!B42 -> 50000 | C24: =Assumptions!B42 -> 50000 | D24: =Assumptions!B42 -> 50000 | E24: =Assumptions!B42 -> 50000 | F24: =Assumptions!B42 -> 50000 | G24: =Assumptions!B42 -> 50000 | H24: =Assumptions!B42 -> 50000 | I24: =Assumptions!B42 -> 50000 | J24: =Assumptions!B42 -> 50000 | K24: =Assumptions!B42 -> 50000
A25: Total Monthly Impressions | B25: =B23*B24 -> 500000 | C25: =C23*C24 -> 900000 | D25: =D23*D24 -> 1500000 | E25: =E23*E24 -> 1900000 | F25: =F23*F24 -> 2500000 | G25: =G23*G24 -> 2750000 | H25: =H23*H24 -> 3000000 | I25: =I23*I24 -> 3250000 | ... K25: =K23*K24 -> 3500000
A26: Engagement Rate | B26: =Assumptions!B43 -> 0.04 | C26: =Assumptions!B43 -> 0.04 | D26: =Assumptions!B43 -> 0.04 | E26: =Assumptions!B43 -> 0.04 | F26: =Assumptions!B43 -> 0.04 | G26: =Assumptions!B43 -> 0.04 | H26: =Assumptions!B43 -> 0.04 | I26: =Assumptions!B43 -> 0.04 | J26: =Assumptions!B43 -> 0.04 | K26: =Assumptions!B43 -> 0.04
A27: Engaged Users / Month | B27: =B25*B26 -> 20000 | C27: =C25*C26 -> 36000 | D27: =D25*D26 -> 60000 | E27: =E25*E26 -> 76000 | F27: =F25*F26 -> 100000 | G27: =G25*G26 -> 110000 | H27: =H25*H26 -> 120000 | I27: =I25*I26 -> 130000 | ... K27: =K25*K26 -> 140000
A28: Clickthrough Rate | B28: =Assumptions!B44 -> 0.02 | C28: =Assumptions!B44 -> 0.02 | D28: =Assumptions!B44 -> 0.02 | E28: =Assumptions!B44 -> 0.02 | F28: =Assumptions!B44 -> 0.02 | G28: =Assumptions!B44 -> 0.02 | H28: =Assumptions!B44 -> 0.02 | I28: =Assumptions!B44 -> 0.02 | J28: =Assumptions!B44 -> 0.02 | K28: =Assumptions!B44 -> 0.02
A29: Monthly Clicks to Website | B29: =B27*B28 -> 400 | C29: =C27*C28 -> 720 | D29: =D27*D28 -> 1200 | E29: =E27*E28 -> 1520 | F29: =F27*F28 -> 2000 | G29: =G27*G28 -> 2200 | H29: =H27*H28 -> 2400 | I29: =I27*I28 -> 2600 | ... K29: =K27*K28 -> 2800
A30: Inquiry Conversion Rate | B30: =Assumptions!B45 -> 0.08 | C30: =Assumptions!B45 -> 0.08 | D30: =Assumptions!B45 -> 0.08 | E30: =Assumptions!B45 -> 0.08 | F30: =Assumptions!B45 -> 0.08 | G30: =Assumptions!B45 -> 0.08 | H30: =Assumptions!B45 -> 0.08 | I30: =Assumptions!B45 -> 0.08 | J30: =Assumptions!B45 -> 0.08 | K30: =Assumptions!B45 -> 0.08
A31: Monthly Inquiries | B31: =B29*B30 -> 32 | C31: =C29*C30 -> 57.6 | D31: =D29*D30 -> 96 | E31: =E29*E30 -> 121.6 | F31: =F29*F30 -> 160 | G31: =G29*G30 -> 176 | H31: =H29*H30 -> 192 | I31: =I29*I30 -> 208 | ... K31: =K29*K30 -> 224
A32: Booking Conversion Rate | B32: =Assumptions!B46 -> 0.25 | C32: =Assumptions!B46 -> 0.25 | D32: =Assumptions!B46 -> 0.25 | E32: =Assumptions!B46 -> 0.25 | F32: =Assumptions!B46 -> 0.25 | G32: =Assumptions!B46 -> 0.25 | H32: =Assumptions!B46 -> 0.25 | I32: =Assumptions!B46 -> 0.25 | J32: =Assumptions!B46 -> 0.25 | K32: =Assumptions!B46 -> 0.25
A33: Monthly Bookings from Creators | B33: =B31*B32 -> 8 | C33: =C31*C32 -> 14.4 | D33: =D31*D32 -> 24 | E33: =E31*E32 -> 30.4 | F33: =F31*F32 -> 40 | G33: =G31*G32 -> 44 | H33: =H31*H32 -> 48 | I33: =I31*I32 -> 52 | ... K33: =K31*K32 -> 56
A34: Annual Bookings from Creators | B34: =B33*12 -> 96 | C34: =C33*12 -> 172.8 | D34: =D33*12 -> 288 | E34: =E33*12 -> 364.8 | F34: =F33*12 -> 480 | G34: =G33*12 -> 528 | H34: =H33*12 -> 576 | I34: =I33*12 -> 624 | ... K34: =K33*12 -> 672
A35: Avg Lesson Revenue per Booking ($) | B35: =B13 -> 85 | C35: =C13 -> 87.55 | D35: =D13 -> 90.1765 | E35: =E13 -> 92.881795 | F35: =F13 -> 95.668249 | G35: =G13 -> 98.538296 | H35: =H13 -> 101.49445 | I35: =I13 -> 104.53928 | ... K35: =K13 -> 110.90572
A36: Platform Rev from Creator Bookings ($) | B36: =B34*B35*Assumptions!B29 -> 979.2 | C36: =C34*C35*Assumptions!B29 -> 1815.4368 | D36: =D34*D35*Assumptions!B29 -> 3116.4998 | E36: =E34*E35*Assumptions!B29 -> 4065.9935 | F36: =F34*F35*Assumptions!B29 -> 5510.4911 | G36: =G34*G35*Assumptions!B29 -> 6243.3865 | H36: =H34*H35*Assumptions!B29 -> 7015.2961 | I36: =I34*I35*Assumptions!B29 -> 7827.9012 | J36: =J34*J35*Assumptions!B29 -> 8434.8646 | K36: =K34*K35*Assumptions!B29 -> 8943.4373
A37: Brand Partnership Rev ($) | B37: =0 -> 0 | C37: =0 -> 0 | D37: =D23*2000 -> 60000 | E37: =E23*3000 -> 114000 | F37: =F23*4000 -> 200000 | G37: =G23*5000 -> 275000 | H37: =H23*6000 -> 360000 | I37: =I23*7000 -> 455000 | J37: =J23*8000 -> 544000 | K37: =K23*10000 -> 700000
A38: TOTAL CREATOR NETWORK REVENUE ($) | B38: =B36+B37 -> 979.2 | C38: =C36+C37 -> 1815.4368 | D38: =D36+D37 -> 63116.5 | E38: =E36+E37 -> 118065.99 | F38: =F36+F37 -> 205510.49 | G38: =G36+G37 -> 281243.39 | H38: =H36+H37 -> 367015.3 | I38: =I36+I37 -> 462827.9 | ... K38: =K36+K37 -> 708943.44
A40: C. TOPGOLF / VENUE PARTNERSHIPS
A41: Active Venue Partners | B41: 2 | C41: 3 | D41: 5 | E41: 6 | F41: 8 | G41: 8 | H41: 8 | I41: 8 | J41: 8 | K41: 8
A42: Avg Annual Foot Traffic per Venue | B42: =Assumptions!B57 -> 500000 | C42: =Assumptions!B57 -> 500000 | D42: =Assumptions!B57 -> 500000 | E42: =Assumptions!B57 -> 500000 | F42: =Assumptions!B57 -> 500000 | G42: =Assumptions!B57 -> 500000 | H42: =Assumptions!B57 -> 500000 | I42: =Assumptions!B57 -> 500000 | J42: =Assumptions!B57 -> 500000 | K42: =Assumptions!B57 -> 500000
A43: Total Venue Traffic | B43: =B41*B42 -> 1000000 | C43: =C41*C42 -> 1500000 | D43: =D41*D42 -> 2500000 | E43: =E41*E42 -> 3000000 | F43: =F41*F42 -> 4000000 | G43: =G41*G42 -> 4000000 | H43: =H41*H42 -> 4000000 | I43: =I41*I42 -> 4000000 | ... K43: =K41*K42 -> 4000000
...

Sheet Cost Build
A1: OPERATING COST BUILD — 10 YEAR FORECAST
B2: Year 1 | C2: Year 2 | D2: Year 3 | E2: Year 4 | F2: Year 5 | G2: Year 6 | H2: Year 7 | I2: Year 8 | J2: Year 9 | K2: Year 10
A4: 1. COST OF REVENUE / DIRECT COSTS
A5: Platform Transaction Processing (3% of GMV) | B5: ='Revenue Build'!B14*0.03 -> 59376.24 | C5: ='Revenue Build'!C14*0.03 -> 101929.21 | D5: ='Revenue Build'!D14*0.03 -> 167979.34 | E5: ='Revenue Build'!E14*0.03 -> 216273.4 | F5: ='Revenue Build'!F14*0.03 -> 289590.09 | G5: ='Revenue Build'!G14*0.03 -> 321222.23 | H5: ='Revenue Build'!H14*0.03 -> 354491.68 | I5: ='Revenue Build'!I14*0.03 -> 389468.19 | ... K5: ='Revenue Build'!K14*0.03 -> 439010.98
A6: Creator Compensation | B6: ='Revenue Build'!B23*Assumptions!B47*12 -> 60000 | C6: ='Revenue Build'!C23*Assumptions!B47*12 -> 108000 | D6: ='Revenue Build'!D23*Assumptions!B47*12 -> 180000 | E6: ='Revenue Build'!E23*Assumptions!B47*12 -> 228000 | F6: ='Revenue Build'!F23*Assumptions!B47*12 -> 300000 | G6: ='Revenue Build'!G23*Assumptions!B47*12 -> 330000 | H6: ='Revenue Build'!H23*Assumptions!B47*12 -> 360000 | I6: ='Revenue Build'!I23*Assumptions!B47*12 -> 390000 | J6: ='Revenue Build'!J23*Assumptions!B47*12 -> 408000 | K6: ='Revenue Build'!K23*Assumptions!B47*12 -> 420000
A7: Creator Content Production Support | B7: ='Revenue Build'!B23*Assumptions!B48*12 -> 24000 | C7: ='Revenue Build'!C23*Assumptions!B48*12 -> 43200 | D7: ='Revenue Build'!D23*Assumptions!B48*12 -> 72000 | E7: ='Revenue Build'!E23*Assumptions!B48*12 -> 91200 | F7: ='Revenue Build'!F23*Assumptions!B48*12 -> 120000 | G7: ='Revenue Build'!G23*Assumptions!B48*12 -> 132000 | H7: ='Revenue Build'!H23*Assumptions!B48*12 -> 144000 | I7: ='Revenue Build'!I23*Assumptions!B48*12 -> 156000 | J7: ='Revenue Build'!J23*Assumptions!B48*12 -> 163200 | K7: ='Revenue Build'!K23*Assumptions!B48*12 -> 168000
A8: Creator Platform Management | B8: ='Revenue Build'!B23*Assumptions!B49*12 -> 12000 | C8: ='Revenue Build'!C23*Assumptions!B49*12 -> 21600 | D8: ='Revenue Build'!D23*Assumptions!B49*12 -> 36000 | E8: ='Revenue Build'!E23*Assumptions!B49*12 -> 45600 | F8: ='Revenue Build'!F23*Assumptions!B49*12 -> 60000 | G8: ='Revenue Build'!G23*Assumptions!B49*12 -> 66000 | H8: ='Revenue Build'!H23*Assumptions!B49*12 -> 72000 | I8: ='Revenue Build'!I23*Assumptions!B49*12 -> 78000 | J8: ='Revenue Build'!J23*Assumptions!B49*12 -> 81600 | K8: ='Revenue Build'!K23*Assumptions!B49*12 -> 84000
A9: Venue Activation Costs | B9: ='Revenue Build'!B41*Assumptions!B64 -> 30000 | C9: ='Revenue Build'!C41*Assumptions!B64 -> 45000 | D9: ='Revenue Build'!D41*Assumptions!B64 -> 75000 | E9: ='Revenue Build'!E41*Assumptions!B64 -> 90000 | F9: ='Revenue Build'!F41*Assumptions!B64 -> 120000 | G9: ='Revenue Build'!G41*Assumptions!B64 -> 120000 | H9: ='Revenue Build'!H41*Assumptions!B64 -> 120000 | I9: ='Revenue Build'!I41*Assumptions!B64 -> 120000 | J9: ='Revenue Build'!J41*Assumptions!B64 -> 120000 | K9: ='Revenue Build'!K41*Assumptions!B64 -> 120000
A10: Corporate Event Delivery (55% of event rev) | B10: ='Revenue Build'!B63*Assumptions!B80 -> 88000 | C10: ='Revenue Build'!C63*Assumptions!B80 -> 211200 | D10: ='Revenue Build'!D63*Assumptions!B80 -> 352000 | E10: ='Revenue Build'!E63*Assumptions!B80 -> 528000 | F10: ='Revenue Build'!F63*Assumptions!B80 -> 792000 | G10: ='Revenue Build'!G63*Assumptions!B80 -> 915200 | H10: ='Revenue Build'!H63*Assumptions!B80 -> 1020800 | I10: ='Revenue Build'!I63*Assumptions!B80 -> 1144000 | J10: ='Revenue Build'!J63*Assumptions!B80 -> 1267200 | K10: ='Revenue Build'!K63*Assumptions!B80 -> 1408000
A11: Direct Sales Commissions (5% of corp rev) | B11: ='Revenue Build'!B71*0.05 -> 9375 | C11: ='Revenue Build'!C71*0.05 -> 27300 | D11: ='Revenue Build'!D71*0.05 -> 45500 | E11: ='Revenue Build'!E71*0.05 -> 68250 | F11: ='Revenue Build'!F71*0.05 -> 102375 | G11: ='Revenue Build'!G71*0.05 -> 118300 | H11: ='Revenue Build'!H71*0.05 -> 131950 | I11: ='Revenue Build'!I71*0.05 -> 147875 | ... K11: ='Revenue Build'!K71*0.05 -> 182000
A12: Customer Service (volume-driven) | B12: ='Revenue Build'!B78*0.02 -> 11696.013 | C12: ='Revenue Build'!C78*0.02 -> 24111.069 | D12: ='Revenue Build'!D78*0.02 -> 41394.901 | E12: ='Revenue Build'!E78*0.02 -> 57542.214 | F12: ='Revenue Build'!F78*0.02 -> 82620.308 | G12: ='Revenue Build'!G78*0.02 -> 93521.63 | H12: ='Revenue Build'!H78*0.02 -> 103950.91 | I12: ='Revenue Build'!I78*0.02 -> 115582.1 | ... K12: ='Revenue Build'!K78*0.02 -> 138836.77
A13: TOTAL DIRECT COSTS | B13: =SUM(B5:B12) -> 294447.25 | C13: =SUM(C5:C12) -> 582340.28 | D13: =SUM(D5:D12) -> 969874.24 | E13: =SUM(E5:E12) -> 1324865.6 | F13: =SUM(F5:F12) -> 1866585.4 | G13: =SUM(G5:G12) -> 2096243.9 | H13: =SUM(H5:H12) -> 2307192.6 | I13: =SUM(I5:I12) -> 2540925.3 | ... K13: =SUM(K5:K12) -> 2959847.8
A15: 2. OPERATING EXPENSES (FIXED + SEMI-VARIABLE)
A16: HEADCOUNT COSTS
A17: CEO / Executive Director | B17: =Assumptions!B86*(1+Assumptions!B95)^0 -> 150000 | C17: =Assumptions!B86*(1+Assumptions!B95)^1 -> 154500 | D17: =Assumptions!B86*(1+Assumptions!B95)^2 -> 159135 | E17: =Assumptions!B86*(1+Assumptions!B95)^3 -> 163909.05 | F17: =Assumptions!B86*(1+Assumptions!B95)^4 -> 168826.32 | G17: =Assumptions!B86*(1+Assumptions!B95)^5 -> 173891.11 | H17: =Assumptions!B86*(1+Assumptions!B95)^6 -> 179107.84 | I17: =Assumptions!B86*(1+Assumptions!B95)^7 -> 184481.08 | J17: =Assumptions!B86*(1+Assumptions!B95)^8 -> 190015.51 | K17: =Assumptions!B86*(1+Assumptions!B95)^9 -> 195715.98
A18: VP Marketing / Growth | B18: =Assumptions!B87*(1+Assumptions!B95)^0 -> 120000 | C18: =Assumptions!B87*(1+Assumptions!B95)^1 -> 123600 | D18: =Assumptions!B87*(1+Assumptions!B95)^2 -> 127308 | E18: =Assumptions!B87*(1+Assumptions!B95)^3 -> 131127.24 | F18: =Assumptions!B87*(1+Assumptions!B95)^4 -> 135061.06 | G18: =Assumptions!B87*(1+Assumptions!B95)^5 -> 139112.89 | H18: =Assumptions!B87*(1+Assumptions!B95)^6 -> 143286.28 | I18: =Assumptions!B87*(1+Assumptions!B95)^7 -> 147584.86 | J18: =Assumptions!B87*(1+Assumptions!B95)^8 -> 152012.41 | K18: =Assumptions!B87*(1+Assumptions!B95)^9 -> 156572.78
A19: Partnership Sales Director | B19: =Assumptions!B88*(1+Assumptions!B95)^0 -> 110000 | C19: =Assumptions!B88*(1+Assumptions!B95)^1 -> 113300 | D19: =Assumptions!B88*(1+Assumptions!B95)^2 -> 116699 | E19: =Assumptions!B88*(1+Assumptions!B95)^3 -> 120199.97 | F19: =Assumptions!B88*(1+Assumptions!B95)^4 -> 123805.97 | G19: =Assumptions!B88*(1+Assumptions!B95)^5 -> 127520.15 | H19: =Assumptions!B88*(1+Assumptions!B95)^6 -> 131345.75 | I19: =Assumptions!B88*(1+Assumptions!B95)^7 -> 135286.13 | J19: =Assumptions!B88*(1+Assumptions!B95)^8 -> 139344.71 | K19: =Assumptions!B88*(1+Assumptions!B95)^9 -> 143525.05
A20: Content & Social Media Manager | B20: =Assumptions!B89*(1+Assumptions!B95)^0 -> 75000 | C20: =Assumptions!B89*(1+Assumptions!B95)^1 -> 77250 | D20: =Assumptions!B89*(1+Assumptions!B95)^2 -> 79567.5 | E20: =Assumptions!B89*(1+Assumptions!B95)^3 -> 81954.525 | F20: =Assumptions!B89*(1+Assumptions!B95)^4 -> 84413.161 | G20: =Assumptions!B89*(1+Assumptions!B95)^5 -> 86945.556 | H20: =Assumptions!B89*(1+Assumptions!B95)^6 -> 89553.922 | I20: =Assumptions!B89*(1+Assumptions!B95)^7 -> 92240.54 | J20: =Assumptions!B89*(1+Assumptions!B95)^8 -> 95007.756 | K20: =Assumptions!B89*(1+Assumptions!B95)^9 -> 97857.989
A21: Platform / Website Manager | B21: =Assumptions!B90*(1+Assumptions!B95)^0 -> 85000 | C21: =Assumptions!B90*(1+Assumptions!B95)^1 -> 87550 | D21: =Assumptions!B90*(1+Assumptions!B95)^2 -> 90176.5 | E21: =Assumptions!B90*(1+Assumptions!B95)^3 -> 92881.795 | F21: =Assumptions!B90*(1+Assumptions!B95)^4 -> 95668.249 | G21: =Assumptions!B90*(1+Assumptions!B95)^5 -> 98538.296 | H21: =Assumptions!B90*(1+Assumptions!B95)^6 -> 101494.45 | I21: =Assumptions!B90*(1+Assumptions!B95)^7 -> 104539.28 | J21: =Assumptions!B90*(1+Assumptions!B95)^8 -> 107675.46 | K21: =Assumptions!B90*(1+Assumptions!B95)^9 -> 110905.72
A22: Customer Support Specialist (Y2+) | B22: =0 -> 0 | C22: =Assumptions!B91*(1+Assumptions!B95)^1 -> 56650 | D22: =Assumptions!B91*(1+Assumptions!B95)^2 -> 58349.5 | E22: =Assumptions!B91*(1+Assumptions!B95)^3 -> 60099.985 | F22: =Assumptions!B91*(1+Assumptions!B95)^4 -> 61902.985 | G22: =Assumptions!B91*(1+Assumptions!B95)^5 -> 63760.074 | H22: =Assumptions!B91*(1+Assumptions!B95)^6 -> 65672.876 | I22: =Assumptions!B91*(1+Assumptions!B95)^7 -> 67643.063 | J22: =Assumptions!B91*(1+Assumptions!B95)^8 -> 69672.354 | K22: =Assumptions!B91*(1+Assumptions!B95)^9 -> 71762.525
A23: Event Coordinator (Y2+) | B23: =0 -> 0 | C23: =Assumptions!B92*(1+Assumptions!B95)^1 -> 61800 | D23: =Assumptions!B92*(1+Assumptions!B95)^2 -> 63654 | E23: =Assumptions!B92*(1+Assumptions!B95)^3 -> 65563.62 | F23: =Assumptions!B92*(1+Assumptions!B95)^4 -> 67530.529 | G23: =Assumptions!B92*(1+Assumptions!B95)^5 -> 69556.444 | H23: =Assumptions!B92*(1+Assumptions!B95)^6 -> 71643.138 | I23: =Assumptions!B92*(1+Assumptions!B95)^7 -> 73792.432 | J23: =Assumptions!B92*(1+Assumptions!B95)^8 -> 76006.205 | K23: =Assumptions!B92*(1+Assumptions!B95)^9 -> 78286.391
A24: Sales Associate — Corporate (Y2+) | B24: =0 -> 0 | C24: =Assumptions!B93*(1+Assumptions!B95)^1 -> 66950 | D24: =Assumptions!B93*(1+Assumptions!B95)^2 -> 68958.5 | E24: =Assumptions!B93*(1+Assumptions!B95)^3 -> 71027.255 | F24: =Assumptions!B93*(1+Assumptions!B95)^4 -> 73158.073 | G24: =Assumptions!B93*(1+Assumptions!B95)^5 -> 75352.815 | H24: =Assumptions!B93*(1+Assumptions!B95)^6 -> 77613.399 | I24: =Assumptions!B93*(1+Assumptions!B95)^7 -> 79941.801 | J24: =Assumptions!B93*(1+Assumptions!B95)^8 -> 82340.055 | K24: =Assumptions!B93*(1+Assumptions!B95)^9 -> 84810.257
A25: Additional Hires (Y4+) | B25: =0*70000*(1+Assumptions!B95)^0 -> 0 | C25: =0*70000*(1+Assumptions!B95)^1 -> 0 | D25: =0*70000*(1+Assumptions!B95)^2 -> 0 | E25: =2*70000*(1+Assumptions!B95)^3 -> 152981.78 | F25: =2*70000*(1+Assumptions!B95)^4 -> 157571.23 | G25: =2*70000*(1+Assumptions!B95)^5 -> 162298.37 | H25: =4*70000*(1+Assumptions!B95)^6 -> 334334.64 | I25: =4*70000*(1+Assumptions!B95)^7 -> 344364.68 | J25: =6*70000*(1+Assumptions!B95)^8 -> 532043.43 | K25: =6*70000*(1+Assumptions!B95)^9 -> 548004.74
A26: Total Base Salaries | B26: =SUM(B17:B25) -> 540000 | C26: =SUM(C17:C25) -> 741600 | D26: =SUM(D17:D25) -> 763848 | E26: =SUM(E17:E25) -> 939745.22 | F26: =SUM(F17:F25) -> 967937.58 | G26: =SUM(G17:G25) -> 996975.7 | H26: =SUM(H17:H25) -> 1194052.3 | I26: =SUM(I17:I25) -> 1229873.9 | ... K26: =SUM(K17:K25) -> 1487441.4
A27: Benefits Load (25%) | B27: =B26*Assumptions!B94 -> 135000 | C27: =C26*Assumptions!B94 -> 185400 | D27: =D26*Assumptions!B94 -> 190962 | E27: =E26*Assumptions!B94 -> 234936.31 | F27: =F26*Assumptions!B94 -> 241984.39 | G27: =G26*Assumptions!B94 -> 249243.93 | H27: =H26*Assumptions!B94 -> 298513.07 | I27: =I26*Assumptions!B94 -> 307468.47 | J27: =J26*Assumptions!B94 -> 361029.47 | K27: =K26*Assumptions!B94 -> 371860.36
A28: TOTAL HEADCOUNT COST | B28: =B26+B27 -> 675000 | C28: =C26+C27 -> 927000 | D28: =D26+D27 -> 954810 | E28: =E26+E27 -> 1174681.5 | F28: =F26+F27 -> 1209922 | G28: =G26+G27 -> 1246219.6 | H28: =H26+H27 -> 1492565.4 | I28: =I26+I27 -> 1537342.3 | ... K28: =K26+K27 -> 1859301.8
A30: NON-HEADCOUNT OPEX
A31: Software / Platform Costs | B31: =Assumptions!B96*(1.05)^0 -> 60000 | C31: =Assumptions!B96*(1.05)^1 -> 63000 | D31: =Assumptions!B96*(1.05)^2 -> 66150 | E31: =Assumptions!B96*(1.05)^3 -> 69457.5 | F31: =Assumptions!B96*(1.05)^4 -> 72930.375 | G31: =Assumptions!B96*(1.05)^5 -> 76576.894 | H31: =Assumptions!B96*(1.05)^6 -> 80405.738 | I31: =Assumptions!B96*(1.05)^7 -> 84426.025 | J31: =Assumptions!B96*(1.05)^8 -> 88647.327 | K31: =Assumptions!B96*(1.05)^9 -> 93079.693
A32: Hosting & Maintenance | B32: =Assumptions!B97*(1.05)^0 -> 18000 | C32: =Assumptions!B97*(1.05)^1 -> 18900 | D32: =Assumptions!B97*(1.05)^2 -> 19845 | E32: =Assumptions!B97*(1.05)^3 -> 20837.25 | F32: =Assumptions!B97*(1.05)^4 -> 21879.112 | G32: =Assumptions!B97*(1.05)^5 -> 22973.068 | H32: =Assumptions!B97*(1.05)^6 -> 24121.722 | I32: =Assumptions!B97*(1.05)^7 -> 25327.808 | J32: =Assumptions!B97*(1.05)^8 -> 26594.198 | K32: =Assumptions!B97*(1.05)^9 -> 27923.908
A33: Content Production Budget | B33: =Assumptions!B98*(1.05)^0 -> 48000 | C33: =Assumptions!B98*(1.05)^1 -> 50400 | D33: =Assumptions!B98*(1.05)^2 -> 52920 | E33: =Assumptions!B98*(1.05)^3 -> 55566 | F33: =Assumptions!B98*(1.05)^4 -> 58344.3 | G33: =Assumptions!B98*(1.05)^5 -> 61261.515 | H33: =Assumptions!B98*(1.05)^6 -> 64324.591 | I33: =Assumptions!B98*(1.05)^7 -> 67540.82 | J33: =Assumptions!B98*(1.05)^8 -> 70917.861 | K33: =Assumptions!B98*(1.05)^9 -> 74463.754
A34: Marketing & Paid Ads | B34: =Assumptions!B99*(1.05)^0 -> 75000 | C34: =Assumptions!B99*(1.05)^1 -> 78750 | D34: =Assumptions!B99*(1.05)^2 -> 82687.5 | E34: =Assumptions!B99*(1.05)^3 -> 86821.875 | F34: =Assumptions!B99*(1.05)^4 -> 91162.969 | G34: =Assumptions!B99*(1.05)^5 -> 95721.117 | H34: =Assumptions!B99*(1.05)^6 -> 100507.17 | I34: =Assumptions!B99*(1.05)^7 -> 105532.53 | J34: =Assumptions!B99*(1.05)^8 -> 110809.16 | K34: =Assumptions!B99*(1.05)^9 -> 116349.62
A35: G&A / Office / Admin | B35: =Assumptions!B100*(1.05)^0 -> 40000 | C35: =Assumptions!B100*(1.05)^1 -> 42000 | D35: =Assumptions!B100*(1.05)^2 -> 44100 | E35: =Assumptions!B100*(1.05)^3 -> 46305 | F35: =Assumptions!B100*(1.05)^4 -> 48620.25 | G35: =Assumptions!B100*(1.05)^5 -> 51051.263 | H35: =Assumptions!B100*(1.05)^6 -> 53603.826 | I35: =Assumptions!B100*(1.05)^7 -> 56284.017 | J35: =Assumptions!B100*(1.05)^8 -> 59098.218 | K35: =Assumptions!B100*(1.05)^9 -> 62053.129
A36: Travel & Event Costs | B36: =Assumptions!B101*(1.05)^0 -> 30000 | C36: =Assumptions!B101*(1.05)^1 -> 31500 | D36: =Assumptions!B101*(1.05)^2 -> 33075 | E36: =Assumptions!B101*(1.05)^3 -> 34728.75 | F36: =Assumptions!B101*(1.05)^4 -> 36465.188 | G36: =Assumptions!B101*(1.05)^5 -> 38288.447 | H36: =Assumptions!B101*(1.05)^6 -> 40202.869 | I36: =Assumptions!B101*(1.05)^7 -> 42213.013 | J36: =Assumptions!B101*(1.05)^8 -> 44323.663 | K36: =Assumptions!B101*(1.05)^9 -> 46539.846
A37: Legal / Compliance | B37: =Assumptions!B102*(1.05)^0 -> 25000 | C37: =Assumptions!B102*(1.05)^1 -> 26250 | D37: =Assumptions!B102*(1.05)^2 -> 27562.5 | E37: =Assumptions!B102*(1.05)^3 -> 28940.625 | F37: =Assumptions!B102*(1.05)^4 -> 30387.656 | G37: =Assumptions!B102*(1.05)^5 -> 31907.039 | H37: =Assumptions!B102*(1.05)^6 -> 33502.391 | I37: =Assumptions!B102*(1.05)^7 -> 35177.511 | J37: =Assumptions!B102*(1.05)^8 -> 36936.386 | K37: =Assumptions!B102*(1.05)^9 -> 38783.205
A38: Insurance | B38: =Assumptions!B103*(1.05)^0 -> 20000 | C38: =Assumptions!B103*(1.05)^1 -> 21000 | D38: =Assumptions!B103*(1.05)^2 -> 22050 | E38: =Assumptions!B103*(1.05)^3 -> 23152.5 | F38: =Assumptions!B103*(1.05)^4 -> 24310.125 | G38: =Assumptions!B103*(1.05)^5 -> 25525.631 | H38: =Assumptions!B103*(1.05)^6 -> 26801.913 | I38: =Assumptions!B103*(1.05)^7 -> 28142.008 | J38: =Assumptions!B103*(1.05)^8 -> 29549.109 | K38: =Assumptions!B103*(1.05)^9 -> 31026.564
A39: Customer Support Tools | B39: =Assumptions!B104*(1.05)^0 -> 15000 | C39: =Assumptions!B104*(1.05)^1 -> 15750 | D39: =Assumptions!B104*(1.05)^2 -> 16537.5 | E39: =Assumptions!B104*(1.05)^3 -> 17364.375 | F39: =Assumptions!B104*(1.05)^4 -> 18232.594 | G39: =Assumptions!B104*(1.05)^5 -> 19144.223 | H39: =Assumptions!B104*(1.05)^6 -> 20101.435 | I39: =Assumptions!B104*(1.05)^7 -> 21106.506 | J39: =Assumptions!B104*(1.05)^8 -> 22161.832 | K39: =Assumptions!B104*(1.05)^9 -> 23269.923
A40: TOTAL NON-HEADCOUNT OPEX | B40: =SUM(B31:B39) -> 331000 | C40: =SUM(C31:C39) -> 347550 | D40: =SUM(D31:D39) -> 364927.5 | E40: =SUM(E31:E39) -> 383173.88 | F40: =SUM(F31:F39) -> 402332.57 | G40: =SUM(G31:G39) -> 422449.2 | H40: =SUM(H31:H39) -> 443571.66 | I40: =SUM(I31:I39) -> 465750.24 | ... K40: =SUM(K31:K39) -> 513489.64
A42: TOTAL OPERATING EXPENSES | B42: =B28+B40 -> 1006000 | C42: =C28+C40 -> 1274550 | D42: =D28+D40 -> 1319737.5 | E42: =E28+E40 -> 1557855.4 | F42: =F28+F40 -> 1612254.5 | G42: =G28+G40 -> 1668668.8 | H42: =H28+H40 -> 1936137 | I42: =I28+I40 -> 2003092.6 | ... K42: =K28+K40 -> 2372791.4
A44: TOTAL COST SUMMARY
A45: Total Direct Costs (COGS) | B45: =B13 -> 294447.25 | C45: =C13 -> 582340.28 | D45: =D13 -> 969874.24 | E45: =E13 -> 1324865.6 | F45: =F13 -> 1866585.4 | G45: =G13 -> 2096243.9 | H45: =H13 -> 2307192.6 | I45: =I13 -> 2540925.3 | ... K45: =K13 -> 2959847.8
...

Sheet Margin Analysis
A1: MARGIN ANALYSIS BY SEGMENT — 10 YEAR FORECAST
B2: Year 1 | C2: Year 2 | D2: Year 3 | E2: Year 4 | F2: Year 5 | G2: Year 6 | H2: Year 7 | I2: Year 8 | J2: Year 9 | K2: Year 10
A4: A. LEARN GOLF PLATFORM — MARGINS
A5: Revenue | B5: ='Revenue Build'!B20 -> 265097.45 | C5: ='Revenue Build'!C20 -> 460846.94 | D5: ='Revenue Build'!D20 -> 768382.19 | E5: ='Revenue Build'!E20 -> 1000032.2 | F5: ='Revenue Build'!F20 -> 1352494.4 | G5: ='Revenue Build'!G20 -> 1503162.3 | H5: ='Revenue Build'!H20 -> 1665684 | I5: ='Revenue Build'!I20 -> 1832755.8 | ... K5: ='Revenue Build'!K20 -> 2066507
A6: Direct Costs (3% processing) | B6: ='Cost Build'!B5 -> 59376.24 | C6: ='Cost Build'!C5 -> 101929.21 | D6: ='Cost Build'!D5 -> 167979.34 | E6: ='Cost Build'!E5 -> 216273.4 | F6: ='Cost Build'!F5 -> 289590.09 | G6: ='Cost Build'!G5 -> 321222.23 | H6: ='Cost Build'!H5 -> 354491.68 | I6: ='Cost Build'!I5 -> 389468.19 | ... K6: ='Cost Build'!K5 -> 439010.98
A7: Gross Profit | B7: =B5-B6 -> 205721.21 | C7: =C5-C6 -> 358917.73 | D7: =D5-D6 -> 600402.85 | E7: =E5-E6 -> 783758.79 | F7: =F5-F6 -> 1062904.4 | G7: =G5-G6 -> 1181940.1 | H7: =H5-H6 -> 1311192.3 | I7: =I5-I6 -> 1443287.6 | ... K7: =K5-K6 -> 1627496
A8: Gross Margin % | B8: =IF(B5=0,0,B7/B5) -> 0.77602108 | C8: =IF(C5=0,0,C7/C5) -> 0.77882198 | D8: =IF(D5=0,0,D7/D5) -> 0.78138569 | E8: =IF(E5=0,0,E7/E5) -> 0.78373356 | F8: =IF(F5=0,0,F7/F5) -> 0.78588445 | G8: =IF(G5=0,0,G7/G5) -> 0.78630237 | H8: =IF(H5=0,0,H7/H5) -> 0.78717951 | I8: =IF(I5=0,0,I7/I5) -> 0.78749586 | ... K8: =IF(K5=0,0,K7/K5) -> 0.78755892
A9: Allocated Overhead (25% of total OpEx) | B9: ='Cost Build'!B42*IF('Revenue Build'!B78=0,0,'Revenue Build'!B20/'Revenue Build'!B78) -> 456032.38 | C9: ='Cost Build'!C42*IF('Revenue Build'!C78=0,0,'Revenue Build'!C20/'Revenue Build'!C78) -> 487222.25 | D9: ='Cost Build'!D42*IF('Revenue Build'!D78=0,0,'Revenue Build'!D20/'Revenue Build'!D78) -> 489945.75 | E9: ='Cost Build'!E42*IF('Revenue Build'!E78=0,0,'Revenue Build'!E20/'Revenue Build'!E78) -> 541482.66 | F9: ='Cost Build'!F42*IF('Revenue Build'!F78=0,0,'Revenue Build'!F20/'Revenue Build'!F78) -> 527852.13 | G9: ='Cost Build'!G42*IF('Revenue Build'!G78=0,0,'Revenue Build'!G20/'Revenue Build'!G78) -> 536406.41 | H9: ='Cost Build'!H42*IF('Revenue Build'!H78=0,0,'Revenue Build'!H20/'Revenue Build'!H78) -> 620483.75 | I9: ='Cost Build'!I42*IF('Revenue Build'!I78=0,0,'Revenue Build'!I20/'Revenue Build'!I78) -> 635250.52 | ... K9: ='Cost Build'!K42*IF('Revenue Build'!K78=0,0,'Revenue Build'!K20/'Revenue Build'!K78) -> 706353.23
A10: Contribution Profit | B10: =B7-B9 -> -250311.17 | C10: =C7-C9 -> -128304.52 | D10: =D7-D9 -> 110457.1 | E10: =E7-E9 -> 242276.13 | F10: =F7-F9 -> 535052.22 | G10: =G7-G9 -> 645533.68 | H10: =H7-H9 -> 690708.57 | I10: =I7-I9 -> 808037.1 | ... K10: =K7-K9 -> 921142.8
A11: Contribution Margin % | B11: =IF(B5=0,0,B10/B5) -> -0.94422325 | C11: =IF(C5=0,0,C10/C5) -> -0.27841027 | D11: =IF(D5=0,0,D10/D5) -> 0.14375281 | E11: =IF(E5=0,0,E10/E5) -> 0.24226833 | F11: =IF(F5=0,0,F10/F5) -> 0.39560401 | G11: =IF(G5=0,0,G10/G5) -> 0.42945041 | H11: =IF(H5=0,0,H10/H5) -> 0.41466963 | I11: =IF(I5=0,0,I10/I5) -> 0.4408864 | ... K11: =IF(K5=0,0,K10/K5) -> 0.4457487
A13: B. CREATOR NETWORK — MARGINS
A14: Revenue | B14: ='Revenue Build'!B38 -> 979.2 | C14: ='Revenue Build'!C38 -> 1815.4368 | D14: ='Revenue Build'!D38 -> 63116.5 | E14: ='Revenue Build'!E38 -> 118065.99 | F14: ='Revenue Build'!F38 -> 205510.49 | G14: ='Revenue Build'!G38 -> 281243.39 | H14: ='Revenue Build'!H38 -> 367015.3 | I14: ='Revenue Build'!I38 -> 462827.9 | ... K14: ='Revenue Build'!K38 -> 708943.44
A15: Direct Costs (Comp + Content + Mgmt) | B15: ='Cost Build'!B6+'Cost Build'!B7+'Cost Build'!B8 -> 96000 | C15: ='Cost Build'!C6+'Cost Build'!C7+'Cost Build'!C8 -> 172800 | D15: ='Cost Build'!D6+'Cost Build'!D7+'Cost Build'!D8 -> 288000 | E15: ='Cost Build'!E6+'Cost Build'!E7+'Cost Build'!E8 -> 364800 | F15: ='Cost Build'!F6+'Cost Build'!F7+'Cost Build'!F8 -> 480000 | G15: ='Cost Build'!G6+'Cost Build'!G7+'Cost Build'!G8 -> 528000 | H15: ='Cost Build'!H6+'Cost Build'!H7+'Cost Build'!H8 -> 576000 | I15: ='Cost Build'!I6+'Cost Build'!I7+'Cost Build'!I8 -> 624000 | ... K15: ='Cost Build'!K6+'Cost Build'!K7+'Cost Build'!K8 -> 672000
A16: Gross Profit | B16: =B14-B15 -> -95020.8 | C16: =C14-C15 -> -170984.56 | D16: =D14-D15 -> -224883.5 | E16: =E14-E15 -> -246734.01 | F16: =F14-F15 -> -274489.51 | G16: =G14-G15 -> -246756.61 | H16: =H14-H15 -> -208984.7 | I16: =I14-I15 -> -161172.1 | ... K16: =K14-K15 -> 36943.437
A17: Gross Margin % | B17: =IF(B14=0,0,B16/B14) -> -97.039216 | C17: =IF(C14=0,0,C16/C14) -> -94.183705 | D17: =IF(D14=0,0,D16/D14) -> -3.5629907 | E17: =IF(E14=0,0,E16/E14) -> -2.0897974 | F17: =IF(F14=0,0,F16/F14) -> -1.3356472 | G17: =IF(G14=0,0,G16/G14) -> -0.87737748 | H17: =IF(H14=0,0,H16/H14) -> -0.56941688 | I17: =IF(I14=0,0,I16/I14) -> -0.34823332 | ... K17: =IF(K14=0,0,K16/K14) -> 0.052110557
A18: Allocated Overhead | B18: ='Cost Build'!B42*IF('Revenue Build'!B78=0,0,'Revenue Build'!B38/'Revenue Build'!B78) -> 1684.4632 | C18: ='Cost Build'!C42*IF('Revenue Build'!C78=0,0,'Revenue Build'!C38/'Revenue Build'!C78) -> 1919.3383 | D18: ='Cost Build'!D42*IF('Revenue Build'!D78=0,0,'Revenue Build'!D38/'Revenue Build'!D78) -> 40245.156 | E18: ='Cost Build'!E42*IF('Revenue Build'!E78=0,0,'Revenue Build'!E38/'Revenue Build'!E78) -> 63928.631 | F18: ='Cost Build'!F42*IF('Revenue Build'!F78=0,0,'Revenue Build'!F38/'Revenue Build'!F78) -> 80206.726 | G18: ='Cost Build'!G42*IF('Revenue Build'!G78=0,0,'Revenue Build'!G38/'Revenue Build'!G78) -> 100362.25 | H18: ='Cost Build'!H42*IF('Revenue Build'!H78=0,0,'Revenue Build'!H38/'Revenue Build'!H78) -> 136716.83 | I18: ='Cost Build'!I42*IF('Revenue Build'!I78=0,0,'Revenue Build'!I38/'Revenue Build'!I78) -> 160420.53 | ... K18: ='Cost Build'!K42*IF('Revenue Build'!K78=0,0,'Revenue Build'!K38/'Revenue Build'!K78) -> 242324.12
A19: Contribution Profit | B19: =B16-B18 -> -96705.263 | C19: =C16-C18 -> -172903.9 | D19: =D16-D18 -> -265128.66 | E19: =E16-E18 -> -310662.64 | F19: =F16-F18 -> -354696.23 | G19: =G16-G18 -> -347118.87 | H19: =H16-H18 -> -345701.53 | I19: =I16-I18 -> -321592.63 | ... K19: =K16-K18 -> -205380.68
A20: Contribution Margin % | B20: =IF(B14=0,0,B19/B14) -> -98.75946 | C20: =IF(C14=0,0,C19/C14) -> -95.240937 | D20: =IF(D14=0,0,D19/D14) -> -4.2006236 | E20: =IF(E14=0,0,E19/E14) -> -2.6312626 | F20: =IF(F14=0,0,F19/F14) -> -1.7259276 | G20: =IF(G14=0,0,G19/G14) -> -1.2342294 | H20: =IF(H14=0,0,H19/H14) -> -0.94192676 | I20: =IF(I14=0,0,I19/I14) -> -0.69484279 | ... K20: =IF(K14=0,0,K19/K14) -> -0.28969967
A22: C. VENUE PARTNERSHIPS — MARGINS
A23: Revenue | B23: ='Revenue Build'!B56 -> 131224 | C23: ='Revenue Build'!C56 -> 196891.08 | D23: ='Revenue Build'!D56 -> 328246.35 | E23: ='Revenue Build'!E56 -> 394012.49 | F23: ='Revenue Build'!F56 -> 525510.49 | G23: ='Revenue Build'!G56 -> 525675.81 | H23: ='Revenue Build'!H56 -> 525846.08 | I23: ='Revenue Build'!I56 -> 526021.46 | ... K23: ='Revenue Build'!K56 -> 526388.17
A24: Direct Costs (Activation) | B24: ='Cost Build'!B9 -> 30000 | C24: ='Cost Build'!C9 -> 45000 | D24: ='Cost Build'!D9 -> 75000 | E24: ='Cost Build'!E9 -> 90000 | F24: ='Cost Build'!F9 -> 120000 | G24: ='Cost Build'!G9 -> 120000 | H24: ='Cost Build'!H9 -> 120000 | I24: ='Cost Build'!I9 -> 120000 | ... K24: ='Cost Build'!K9 -> 120000
A25: Gross Profit | B25: =B23-B24 -> 101224 | C25: =C23-C24 -> 151891.08 | D25: =D23-D24 -> 253246.35 | E25: =E23-E24 -> 304012.49 | F25: =F23-F24 -> 405510.49 | G25: =G23-G24 -> 405675.81 | H25: =H23-H24 -> 405846.08 | I25: =I23-I24 -> 406021.46 | ... K25: =K23-K24 -> 406388.17
A26: Gross Margin % | B26: =IF(B23=0,0,B25/B23) -> 0.77138328 | C26: =IF(C23=0,0,C25/C23) -> 0.77144724 | D26: =IF(D23=0,0,D25/D23) -> 0.77151308 | E26: =IF(E23=0,0,E25/E23) -> 0.77158085 | F26: =IF(F23=0,0,F25/F23) -> 0.77165061 | G26: =IF(G23=0,0,G25/G23) -> 0.77172242 | H26: =IF(H23=0,0,H25/H23) -> 0.77179634 | I26: =IF(I23=0,0,I25/I23) -> 0.77187243 | ... K26: =IF(K23=0,0,K25/K23) -> 0.77203135
A27: Allocated Overhead | B27: ='Cost Build'!B42*IF('Revenue Build'!B78=0,0,'Revenue Build'!B56/'Revenue Build'!B78) -> 225737.34 | C27: ='Cost Build'!C42*IF('Revenue Build'!C78=0,0,'Revenue Build'!C56/'Revenue Build'!C78) -> 208159.6 | D27: ='Cost Build'!D42*IF('Revenue Build'!D78=0,0,'Revenue Build'!D56/'Revenue Build'!D78) -> 209300.67 | E27: ='Cost Build'!E42*IF('Revenue Build'!E78=0,0,'Revenue Build'!E56/'Revenue Build'!E78) -> 213344.07 | F27: ='Cost Build'!F42*IF('Revenue Build'!F78=0,0,'Revenue Build'!F56/'Revenue Build'!F78) -> 205096.47 | G27: ='Cost Build'!G42*IF('Revenue Build'!G78=0,0,'Revenue Build'!G56/'Revenue Build'!G78) -> 187588.44 | H27: ='Cost Build'!H42*IF('Revenue Build'!H78=0,0,'Revenue Build'!H56/'Revenue Build'!H78) -> 195882.86 | I27: ='Cost Build'!I42*IF('Revenue Build'!I78=0,0,'Revenue Build'!I56/'Revenue Build'!I78) -> 182324.02 | ... K27: ='Cost Build'!K42*IF('Revenue Build'!K78=0,0,'Revenue Build'!K56/'Revenue Build'!K78) -> 179924.86
A28: Contribution Profit | B28: =B25-B27 -> -124513.34 | C28: =C25-C27 -> -56268.52 | D28: =D25-D27 -> 43945.685 | E28: =E25-E27 -> 90668.427 | F28: =F25-F27 -> 200414.02 | G28: =G25-G27 -> 218087.37 | H28: =H25-H27 -> 209963.22 | I28: =I25-I27 -> 223697.44 | ... K28: =K25-K27 -> 226463.31
A29: Contribution Margin % | B29: =IF(B23=0,0,B28/B23) -> -0.94886105 | C29: =IF(C23=0,0,C28/C23) -> -0.28578502 | D29: =IF(D23=0,0,D28/D23) -> 0.13388019 | E29: =IF(E23=0,0,E28/E23) -> 0.23011561 | F29: =IF(F23=0,0,F28/F23) -> 0.38137016 | G29: =IF(G23=0,0,G28/G23) -> 0.41487047 | H29: =IF(H23=0,0,H28/H23) -> 0.39928646 | I29: =IF(I23=0,0,I28/I23) -> 0.42526296 | ... K29: =IF(K23=0,0,K28/K23) -> 0.43022112
A31: D. CORPORATE PROGRAMS — MARGINS
A32: Revenue | B32: ='Revenue Build'!B71 -> 187500 | C32: ='Revenue Build'!C71 -> 546000 | D32: ='Revenue Build'!D71 -> 910000 | E32: ='Revenue Build'!E71 -> 1365000 | F32: ='Revenue Build'!F71 -> 2047500 | G32: ='Revenue Build'!G71 -> 2366000 | H32: ='Revenue Build'!H71 -> 2639000 | I32: ='Revenue Build'!I71 -> 2957500 | ... K32: ='Revenue Build'!K71 -> 3640000
A33: Direct Costs (Delivery + Commissions) | B33: ='Cost Build'!B10+'Cost Build'!B11 -> 97375 | C33: ='Cost Build'!C10+'Cost Build'!C11 -> 238500 | D33: ='Cost Build'!D10+'Cost Build'!D11 -> 397500 | E33: ='Cost Build'!E10+'Cost Build'!E11 -> 596250 | F33: ='Cost Build'!F10+'Cost Build'!F11 -> 894375 | G33: ='Cost Build'!G10+'Cost Build'!G11 -> 1033500 | H33: ='Cost Build'!H10+'Cost Build'!H11 -> 1152750 | I33: ='Cost Build'!I10+'Cost Build'!I11 -> 1291875 | ... K33: ='Cost Build'!K10+'Cost Build'!K11 -> 1590000
A34: Gross Profit | B34: =B32-B33 -> 90125 | C34: =C32-C33 -> 307500 | D34: =D32-D33 -> 512500 | E34: =E32-E33 -> 768750 | F34: =F32-F33 -> 1153125 | G34: =G32-G33 -> 1332500 | H34: =H32-H33 -> 1486250 | I34: =I32-I33 -> 1665625 | ... K34: =K32-K33 -> 2050000
A35: Gross Margin % | B35: =IF(B32=0,0,B34/B32) -> 0.48066667 | C35: =IF(C32=0,0,C34/C32) -> 0.56318681 | D35: =IF(D32=0,0,D34/D32) -> 0.56318681 | E35: =IF(E32=0,0,E34/E32) -> 0.56318681 | F35: =IF(F32=0,0,F34/F32) -> 0.56318681 | G35: =IF(G32=0,0,G34/G32) -> 0.56318681 | H35: =IF(H32=0,0,H34/H32) -> 0.56318681 | I35: =IF(I32=0,0,I34/I32) -> 0.56318681 | ... K35: =IF(K32=0,0,K34/K32) -> 0.56318681
A36: Allocated Overhead | B36: ='Cost Build'!B42*IF('Revenue Build'!B78=0,0,'Revenue Build'!B71/'Revenue Build'!B78) -> 322545.81 | C36: ='Cost Build'!C42*IF('Revenue Build'!C78=0,0,'Revenue Build'!C71/'Revenue Build'!C78) -> 577248.81 | D36: ='Cost Build'!D42*IF('Revenue Build'!D78=0,0,'Revenue Build'!D71/'Revenue Build'!D78) -> 580245.92 | E36: ='Cost Build'!E42*IF('Revenue Build'!E78=0,0,'Revenue Build'!E71/'Revenue Build'!E78) -> 739100.04 | F36: ='Cost Build'!F42*IF('Revenue Build'!F78=0,0,'Revenue Build'!F71/'Revenue Build'!F78) -> 799099.21 | G36: ='Cost Build'!G42*IF('Revenue Build'!G78=0,0,'Revenue Build'!G71/'Revenue Build'!G78) -> 844311.72 | H36: ='Cost Build'!H42*IF('Revenue Build'!H78=0,0,'Revenue Build'!H71/'Revenue Build'!H78) -> 983053.59 | I36: ='Cost Build'!I42*IF('Revenue Build'!I78=0,0,'Revenue Build'!I71/'Revenue Build'!I78) -> 1025097.5 | ... K36: ='Cost Build'!K42*IF('Revenue Build'!K78=0,0,'Revenue Build'!K71/'Revenue Build'!K78) -> 1244189.2
A37: Contribution Profit | B37: =B34-B36 -> -232420.81 | C37: =C34-C36 -> -269748.81 | D37: =D34-D36 -> -67745.923 | E37: =E34-E36 -> 29649.958 | F37: =F34-F36 -> 354025.79 | G37: =G34-G36 -> 488188.28 | H37: =H34-H36 -> 503196.41 | I37: =I34-I36 -> 640527.5 | ... K37: =K34-K36 -> 805810.78
A38: Contribution Margin % | B38: =IF(B32=0,0,B37/B32) -> -1.2395777 | C38: =IF(C32=0,0,C37/C32) -> -0.49404544 | D38: =IF(D32=0,0,D37/D32) -> -0.074446069 | E38: =IF(E32=0,0,E37/E32) -> 0.021721581 | F38: =IF(F32=0,0,F37/F32) -> 0.17290637 | G38: =IF(G32=0,0,G37/G32) -> 0.20633486 | H38: =IF(H32=0,0,H37/H32) -> 0.19067693 | I38: =IF(I32=0,0,I37/I32) -> 0.21657734 | ... K38: =IF(K32=0,0,K37/K32) -> 0.22137659
A40: CONSOLIDATED MARGIN SUMMARY
A41: Total Revenue | B41: ='Revenue Build'!B78 -> 584800.65 | C41: ='Revenue Build'!C78 -> 1205553.5 | D41: ='Revenue Build'!D78 -> 2069745 | E41: ='Revenue Build'!E78 -> 2877110.7 | F41: ='Revenue Build'!F78 -> 4131015.4 | G41: ='Revenue Build'!G78 -> 4676081.5 | H41: ='Revenue Build'!H78 -> 5197545.4 | I41: ='Revenue Build'!I78 -> 5779105.2 | ... K41: ='Revenue Build'!K78 -> 6941838.6
A42: Total Direct Costs | B42: ='Cost Build'!B13 -> 294447.25 | C42: ='Cost Build'!C13 -> 582340.28 | D42: ='Cost Build'!D13 -> 969874.24 | E42: ='Cost Build'!E13 -> 1324865.6 | F42: ='Cost Build'!F13 -> 1866585.4 | G42: ='Cost Build'!G13 -> 2096243.9 | H42: ='Cost Build'!H13 -> 2307192.6 | I42: ='Cost Build'!I13 -> 2540925.3 | ... K42: ='Cost Build'!K13 -> 2959847.8
A43: GROSS PROFIT | B43: =B41-B42 -> 290353.4 | C43: =C41-C42 -> 623213.18 | D43: =D41-D42 -> 1099870.8 | E43: =E41-E42 -> 1552245.1 | F43: =F41-F42 -> 2264430 | G43: =G41-G42 -> 2579837.7 | H43: =H41-H42 -> 2890352.8 | I43: =I41-I42 -> 3238179.9 | ... K43: =K41-K42 -> 3981990.9
A44: GROSS MARGIN % | B44: =IF(B41=0,0,B43/B41) -> 0.49649978 | C44: =IF(C41=0,0,C43/C41) -> 0.51695192 | D44: =IF(D41=0,0,D43/D41) -> 0.531404 | E44: =IF(E41=0,0,E43/E41) -> 0.53951524 | F44: =IF(F41=0,0,F43/F41) -> 0.54815337 | G44: =IF(G41=0,0,G43/G41) -> 0.5517093 | H44: =IF(H41=0,0,H43/H41) -> 0.55609958 | I44: =IF(I41=0,0,I43/I41) -> 0.56032548 | ... K44: =IF(K41=0,0,K43/K41) -> 0.57362193
A46: Total Operating Expenses | B46: ='Cost Build'!B42 -> 1006000 | C46: ='Cost Build'!C42 -> 1274550 | D46: ='Cost Build'!D42 -> 1319737.5 | E46: ='Cost Build'!E42 -> 1557855.4 | F46: ='Cost Build'!F42 -> 1612254.5 | G46: ='Cost Build'!G42 -> 1668668.8 | H46: ='Cost Build'!H42 -> 1936137 | I46: ='Cost Build'!I42 -> 2003092.6 | ... K46: ='Cost Build'!K42 -> 2372791.4
...

Sheet 10-Yr Projection
A1: 10-YEAR FINANCIAL PROJECTION — INCOME STATEMENT & CASH FLOW
A2: ($) | B2: Year 1 | C2: Year 2 | D2: Year 3 | E2: Year 4 | F2: Year 5 | G2: Year 6 | H2: Year 7 | I2: Year 8 | J2: Year 9 | K2: Year 10
A4: INCOME STATEMENT
A5: Platform Revenue | B5: ='Revenue Build'!B20 -> 265097.45 | C5: ='Revenue Build'!C20 -> 460846.94 | D5: ='Revenue Build'!D20 -> 768382.19 | E5: ='Revenue Build'!E20 -> 1000032.2 | F5: ='Revenue Build'!F20 -> 1352494.4 | G5: ='Revenue Build'!G20 -> 1503162.3 | H5: ='Revenue Build'!H20 -> 1665684 | I5: ='Revenue Build'!I20 -> 1832755.8 | ... K5: ='Revenue Build'!K20 -> 2066507
A6: Creator Revenue | B6: ='Revenue Build'!B38 -> 979.2 | C6: ='Revenue Build'!C38 -> 1815.4368 | D6: ='Revenue Build'!D38 -> 63116.5 | E6: ='Revenue Build'!E38 -> 118065.99 | F6: ='Revenue Build'!F38 -> 205510.49 | G6: ='Revenue Build'!G38 -> 281243.39 | H6: ='Revenue Build'!H38 -> 367015.3 | I6: ='Revenue Build'!I38 -> 462827.9 | ... K6: ='Revenue Build'!K38 -> 708943.44
A7: Venue Revenue | B7: ='Revenue Build'!B56 -> 131224 | C7: ='Revenue Build'!C56 -> 196891.08 | D7: ='Revenue Build'!D56 -> 328246.35 | E7: ='Revenue Build'!E56 -> 394012.49 | F7: ='Revenue Build'!F56 -> 525510.49 | G7: ='Revenue Build'!G56 -> 525675.81 | H7: ='Revenue Build'!H56 -> 525846.08 | I7: ='Revenue Build'!I56 -> 526021.46 | ... K7: ='Revenue Build'!K56 -> 526388.17
A8: Corporate Revenue | B8: ='Revenue Build'!B71 -> 187500 | C8: ='Revenue Build'!C71 -> 546000 | D8: ='Revenue Build'!D71 -> 910000 | E8: ='Revenue Build'!E71 -> 1365000 | F8: ='Revenue Build'!F71 -> 2047500 | G8: ='Revenue Build'!G71 -> 2366000 | H8: ='Revenue Build'!H71 -> 2639000 | I8: ='Revenue Build'!I71 -> 2957500 | ... K8: ='Revenue Build'!K71 -> 3640000
A9: TOTAL REVENUE | B9: =SUM(B5:B8) -> 584800.65 | C9: =SUM(C5:C8) -> 1205553.5 | D9: =SUM(D5:D8) -> 2069745 | E9: =SUM(E5:E8) -> 2877110.7 | F9: =SUM(F5:F8) -> 4131015.4 | G9: =SUM(G5:G8) -> 4676081.5 | H9: =SUM(H5:H8) -> 5197545.4 | I9: =SUM(I5:I8) -> 5779105.2 | ... K9: =SUM(K5:K8) -> 6941838.6
A11: Platform Direct Costs | B11: ='Cost Build'!B5 -> 59376.24 | C11: ='Cost Build'!C5 -> 101929.21 | D11: ='Cost Build'!D5 -> 167979.34 | E11: ='Cost Build'!E5 -> 216273.4 | F11: ='Cost Build'!F5 -> 289590.09 | G11: ='Cost Build'!G5 -> 321222.23 | H11: ='Cost Build'!H5 -> 354491.68 | I11: ='Cost Build'!I5 -> 389468.19 | ... K11: ='Cost Build'!K5 -> 439010.98
A12: Creator Direct Costs | B12: ='Cost Build'!B6+'Cost Build'!B7+'Cost Build'!B8 -> 96000 | C12: ='Cost Build'!C6+'Cost Build'!C7+'Cost Build'!C8 -> 172800 | D12: ='Cost Build'!D6+'Cost Build'!D7+'Cost Build'!D8 -> 288000 | E12: ='Cost Build'!E6+'Cost Build'!E7+'Cost Build'!E8 -> 364800 | F12: ='Cost Build'!F6+'Cost Build'!F7+'Cost Build'!F8 -> 480000 | G12: ='Cost Build'!G6+'Cost Build'!G7+'Cost Build'!G8 -> 528000 | H12: ='Cost Build'!H6+'Cost Build'!H7+'Cost Build'!H8 -> 576000 | I12: ='Cost Build'!I6+'Cost Build'!I7+'Cost Build'!I8 -> 624000 | ... K12: ='Cost Build'!K6+'Cost Build'!K7+'Cost Build'!K8 -> 672000
A13: Venue Direct Costs | B13: ='Cost Build'!B9 -> 30000 | C13: ='Cost Build'!C9 -> 45000 | D13: ='Cost Build'!D9 -> 75000 | E13: ='Cost Build'!E9 -> 90000 | F13: ='Cost Build'!F9 -> 120000 | G13: ='Cost Build'!G9 -> 120000 | H13: ='Cost Build'!H9 -> 120000 | I13: ='Cost Build'!I9 -> 120000 | ... K13: ='Cost Build'!K9 -> 120000
A14: Corporate Direct Costs | B14: ='Cost Build'!B10+'Cost Build'!B11 -> 97375 | C14: ='Cost Build'!C10+'Cost Build'!C11 -> 238500 | D14: ='Cost Build'!D10+'Cost Build'!D11 -> 397500 | E14: ='Cost Build'!E10+'Cost Build'!E11 -> 596250 | F14: ='Cost Build'!F10+'Cost Build'!F11 -> 894375 | G14: ='Cost Build'!G10+'Cost Build'!G11 -> 1033500 | H14: ='Cost Build'!H10+'Cost Build'!H11 -> 1152750 | I14: ='Cost Build'!I10+'Cost Build'!I11 -> 1291875 | ... K14: ='Cost Build'!K10+'Cost Build'!K11 -> 1590000
A15: Other Direct Costs | B15: ='Cost Build'!B12 -> 11696.013 | C15: ='Cost Build'!C12 -> 24111.069 | D15: ='Cost Build'!D12 -> 41394.901 | E15: ='Cost Build'!E12 -> 57542.214 | F15: ='Cost Build'!F12 -> 82620.308 | G15: ='Cost Build'!G12 -> 93521.63 | H15: ='Cost Build'!H12 -> 103950.91 | I15: ='Cost Build'!I12 -> 115582.1 | ... K15: ='Cost Build'!K12 -> 138836.77
A16: TOTAL COGS | B16: =SUM(B11:B15) -> 294447.25 | C16: =SUM(C11:C15) -> 582340.28 | D16: =SUM(D11:D15) -> 969874.24 | E16: =SUM(E11:E15) -> 1324865.6 | F16: =SUM(F11:F15) -> 1866585.4 | G16: =SUM(G11:G15) -> 2096243.9 | H16: =SUM(H11:H15) -> 2307192.6 | I16: =SUM(I11:I15) -> 2540925.3 | ... K16: =SUM(K11:K15) -> 2959847.8
A18: GROSS PROFIT | B18: =B9-B16 -> 290353.4 | C18: =C9-C16 -> 623213.18 | D18: =D9-D16 -> 1099870.8 | E18: =E9-E16 -> 1552245.1 | F18: =F9-F16 -> 2264430 | G18: =G9-G16 -> 2579837.7 | H18: =H9-H16 -> 2890352.8 | I18: =I9-I16 -> 3238179.9 | ... K18: =K9-K16 -> 3981990.9
A19: Gross Margin % | B19: =IF(B9=0,0,B18/B9) -> 0.49649978 | C19: =IF(C9=0,0,C18/C9) -> 0.51695192 | D19: =IF(D9=0,0,D18/D9) -> 0.531404 | E19: =IF(E9=0,0,E18/E9) -> 0.53951524 | F19: =IF(F9=0,0,F18/F9) -> 0.54815337 | G19: =IF(G9=0,0,G18/G9) -> 0.5517093 | H19: =IF(H9=0,0,H18/H9) -> 0.55609958 | I19: =IF(I9=0,0,I18/I9) -> 0.56032548 | ... K19: =IF(K9=0,0,K18/K9) -> 0.57362193
A21: Headcount Costs | B21: ='Cost Build'!B28 -> 675000 | C21: ='Cost Build'!C28 -> 927000 | D21: ='Cost Build'!D28 -> 954810 | E21: ='Cost Build'!E28 -> 1174681.5 | F21: ='Cost Build'!F28 -> 1209922 | G21: ='Cost Build'!G28 -> 1246219.6 | H21: ='Cost Build'!H28 -> 1492565.4 | I21: ='Cost Build'!I28 -> 1537342.3 | ... K21: ='Cost Build'!K28 -> 1859301.8
A22: Non-Headcount OpEx | B22: ='Cost Build'!B40 -> 331000 | C22: ='Cost Build'!C40 -> 347550 | D22: ='Cost Build'!D40 -> 364927.5 | E22: ='Cost Build'!E40 -> 383173.88 | F22: ='Cost Build'!F40 -> 402332.57 | G22: ='Cost Build'!G40 -> 422449.2 | H22: ='Cost Build'!H40 -> 443571.66 | I22: ='Cost Build'!I40 -> 465750.24 | ... K22: ='Cost Build'!K40 -> 513489.64
A23: TOTAL OPERATING EXPENSES | B23: =B21+B22 -> 1006000 | C23: =C21+C22 -> 1274550 | D23: =D21+D22 -> 1319737.5 | E23: =E21+E22 -> 1557855.4 | F23: =F21+F22 -> 1612254.5 | G23: =G21+G22 -> 1668668.8 | H23: =H21+H22 -> 1936137 | I23: =I21+I22 -> 2003092.6 | ... K23: =K21+K22 -> 2372791.4
A25: EBITDA | B25: =B18-B23 -> -715646.6 | C25: =C18-C23 -> -651336.82 | D25: =D18-D23 -> -219866.69 | E25: =E18-E23 -> -5610.34 | F25: =F18-F23 -> 652175.49 | G25: =G18-G23 -> 911168.83 | H25: =H18-H23 -> 954215.76 | I25: =I18-I23 -> 1235087.3 | ... K25: =K18-K23 -> 1609199.4
A26: EBITDA Margin % | B26: =IF(B9=0,0,B25/B9) -> -1.2237445 | C26: =IF(C9=0,0,C25/C9) -> -0.54028033 | D26: =IF(D9=0,0,D25/D9) -> -0.10622888 | E26: =IF(E9=0,0,E25/E9) -> -0.001949991 | F26: =IF(F9=0,0,F25/F9) -> 0.15787292 | G26: =IF(G9=0,0,G25/G9) -> 0.19485735 | H26: =IF(H9=0,0,H25/H9) -> 0.18358969 | I26: =IF(I9=0,0,I25/I9) -> 0.21371601 | ... K26: =IF(K9=0,0,K25/K9) -> 0.2318117
A28: Depreciation & Amortization | B28: =B9*Assumptions!B120 -> 17544.019 | C28: =C9*Assumptions!B120 -> 36166.604 | D28: =D9*Assumptions!B120 -> 62092.351 | E28: =E9*Assumptions!B120 -> 86313.32 | F28: =F9*Assumptions!B120 -> 123930.46 | G28: =G9*Assumptions!B120 -> 140282.45 | H28: =H9*Assumptions!B120 -> 155926.36 | I28: =I9*Assumptions!B120 -> 173373.16 | J28: =J9*Assumptions!B120 -> 188634.23 | K28: =K9*Assumptions!B120 -> 208255.16
A29: EBIT | B29: =B25-B28 -> -733190.62 | C29: =C25-C28 -> -687503.43 | D29: =D25-D28 -> -281959.05 | E29: =E25-E28 -> -91923.66 | F29: =F25-F28 -> 528245.02 | G29: =G25-G28 -> 770886.39 | H29: =H25-H28 -> 798289.4 | I29: =I25-I28 -> 1061714.2 | ... K29: =K25-K28 -> 1400944.3
A30: EBIT Margin % | B30: =IF(B9=0,0,B29/B9) -> -1.2537445 | C30: =IF(C9=0,0,C29/C9) -> -0.57028033 | D30: =IF(D9=0,0,D29/D9) -> -0.13622888 | E30: =IF(E9=0,0,E29/E9) -> -0.031949991 | F30: =IF(F9=0,0,F29/F9) -> 0.12787292 | G30: =IF(G9=0,0,G29/G9) -> 0.16485735 | H30: =IF(H9=0,0,H29/H9) -> 0.15358969 | I30: =IF(I9=0,0,I29/I9) -> 0.18371601 | ... K30: =IF(K9=0,0,K29/K9) -> 0.2018117
